{
  "nbformat": 4,
  "nbformat_minor": 0,
  "metadata": {
    "colab": {
      "provenance": [],
      "mount_file_id": "1HxD4xdX1Dt8SHFlOqS_D6WkgE2bzoE-f",
      "authorship_tag": "ABX9TyOCM1ubICpN8A1yhXHWGFo8",
      "include_colab_link": true
    },
    "kernelspec": {
      "name": "python3",
      "display_name": "Python 3"
    },
    "language_info": {
      "name": "python"
    }
  },
  "cells": [
    {
      "cell_type": "markdown",
      "metadata": {
        "id": "view-in-github",
        "colab_type": "text"
      },
      "source": [
        "<a href=\"https://colab.research.google.com/github/Ocrabit/Hackathon2024/blob/main/ZipCodeConversionData.ipynb\" target=\"_parent\"><img src=\"https://colab.research.google.com/assets/colab-badge.svg\" alt=\"Open In Colab\"/></a>"
      ]
    },
    {
      "cell_type": "code",
      "source": [
        "pip install uszipcode"
      ],
      "metadata": {
        "colab": {
          "base_uri": "https://localhost:8080/"
        },
        "id": "_nG9CmzTj4Io",
        "outputId": "114bb53c-579c-434a-f8d2-7c2dc073b5da"
      },
      "execution_count": null,
      "outputs": [
        {
          "output_type": "stream",
          "name": "stdout",
          "text": [
            "Collecting uszipcode\n",
            "  Downloading uszipcode-1.0.1-py2.py3-none-any.whl (35 kB)\n",
            "Requirement already satisfied: attrs in /usr/local/lib/python3.10/dist-packages (from uszipcode) (23.2.0)\n",
            "Requirement already satisfied: requests in /usr/local/lib/python3.10/dist-packages (from uszipcode) (2.31.0)\n",
            "Collecting pathlib-mate (from uszipcode)\n",
            "  Downloading pathlib_mate-1.3.2-py3-none-any.whl (56 kB)\n",
            "\u001b[2K     \u001b[90m━━━━━━━━━━━━━━━━━━━━━━━━━━━━━━━━━━━━━━━━\u001b[0m \u001b[32m57.0/57.0 kB\u001b[0m \u001b[31m3.5 MB/s\u001b[0m eta \u001b[36m0:00:00\u001b[0m\n",
            "\u001b[?25hCollecting atomicwrites (from uszipcode)\n",
            "  Downloading atomicwrites-1.4.1.tar.gz (14 kB)\n",
            "  Preparing metadata (setup.py) ... \u001b[?25l\u001b[?25hdone\n",
            "Collecting fuzzywuzzy (from uszipcode)\n",
            "  Downloading fuzzywuzzy-0.18.0-py2.py3-none-any.whl (18 kB)\n",
            "Collecting haversine>=2.5.0 (from uszipcode)\n",
            "  Downloading haversine-2.8.1-py2.py3-none-any.whl (7.7 kB)\n",
            "Requirement already satisfied: SQLAlchemy>=1.4.0 in /usr/local/lib/python3.10/dist-packages (from uszipcode) (2.0.29)\n",
            "Collecting sqlalchemy-mate>=1.4.28.3 (from uszipcode)\n",
            "  Downloading sqlalchemy_mate-1.4.28.4-py2.py3-none-any.whl (77 kB)\n",
            "\u001b[2K     \u001b[90m━━━━━━━━━━━━━━━━━━━━━━━━━━━━━━━━━━━━━━━━\u001b[0m \u001b[32m77.1/77.1 kB\u001b[0m \u001b[31m4.5 MB/s\u001b[0m eta \u001b[36m0:00:00\u001b[0m\n",
            "\u001b[?25hRequirement already satisfied: typing-extensions>=4.6.0 in /usr/local/lib/python3.10/dist-packages (from SQLAlchemy>=1.4.0->uszipcode) (4.10.0)\n",
            "Requirement already satisfied: greenlet!=0.4.17 in /usr/local/lib/python3.10/dist-packages (from SQLAlchemy>=1.4.0->uszipcode) (3.0.3)\n",
            "Collecting SQLAlchemy>=1.4.0 (from uszipcode)\n",
            "  Downloading SQLAlchemy-1.4.52-cp310-cp310-manylinux_2_5_x86_64.manylinux1_x86_64.manylinux_2_17_x86_64.manylinux2014_x86_64.whl (1.6 MB)\n",
            "\u001b[2K     \u001b[90m━━━━━━━━━━━━━━━━━━━━━━━━━━━━━━━━━━━━━━━━\u001b[0m \u001b[32m1.6/1.6 MB\u001b[0m \u001b[31m11.5 MB/s\u001b[0m eta \u001b[36m0:00:00\u001b[0m\n",
            "\u001b[?25hRequirement already satisfied: prettytable in /usr/local/lib/python3.10/dist-packages (from sqlalchemy-mate>=1.4.28.3->uszipcode) (3.10.0)\n",
            "Requirement already satisfied: charset-normalizer<4,>=2 in /usr/local/lib/python3.10/dist-packages (from requests->uszipcode) (3.3.2)\n",
            "Requirement already satisfied: idna<4,>=2.5 in /usr/local/lib/python3.10/dist-packages (from requests->uszipcode) (3.6)\n",
            "Requirement already satisfied: urllib3<3,>=1.21.1 in /usr/local/lib/python3.10/dist-packages (from requests->uszipcode) (2.0.7)\n",
            "Requirement already satisfied: certifi>=2017.4.17 in /usr/local/lib/python3.10/dist-packages (from requests->uszipcode) (2024.2.2)\n",
            "Requirement already satisfied: wcwidth in /usr/local/lib/python3.10/dist-packages (from prettytable->sqlalchemy-mate>=1.4.28.3->uszipcode) (0.2.13)\n",
            "Building wheels for collected packages: atomicwrites\n",
            "  Building wheel for atomicwrites (setup.py) ... \u001b[?25l\u001b[?25hdone\n",
            "  Created wheel for atomicwrites: filename=atomicwrites-1.4.1-py2.py3-none-any.whl size=6941 sha256=eda72c38592b3d0049013295d0da2d11d588b4b6394881ca67404b1bfb59c3ba\n",
            "  Stored in directory: /root/.cache/pip/wheels/34/07/0b/33b15f68736109f72ea0bb2499521d87312b932620737447a2\n",
            "Successfully built atomicwrites\n",
            "Installing collected packages: fuzzywuzzy, SQLAlchemy, pathlib-mate, haversine, atomicwrites, sqlalchemy-mate, uszipcode\n",
            "  Attempting uninstall: SQLAlchemy\n",
            "    Found existing installation: SQLAlchemy 2.0.29\n",
            "    Uninstalling SQLAlchemy-2.0.29:\n",
            "      Successfully uninstalled SQLAlchemy-2.0.29\n",
            "\u001b[31mERROR: pip's dependency resolver does not currently take into account all the packages that are installed. This behaviour is the source of the following dependency conflicts.\n",
            "ipython-sql 0.5.0 requires sqlalchemy>=2.0, but you have sqlalchemy 1.4.52 which is incompatible.\u001b[0m\u001b[31m\n",
            "\u001b[0mSuccessfully installed SQLAlchemy-1.4.52 atomicwrites-1.4.1 fuzzywuzzy-0.18.0 haversine-2.8.1 pathlib-mate-1.3.2 sqlalchemy-mate-1.4.28.4 uszipcode-1.0.1\n"
          ]
        }
      ]
    },
    {
      "cell_type": "code",
      "source": [
        "import numpy as np\n",
        "import seaborn as sns\n",
        "from matplotlib import pyplot as plt\n",
        "import pandas as pd\n",
        "from uszipcode import SearchEngine"
      ],
      "metadata": {
        "colab": {
          "base_uri": "https://localhost:8080/"
        },
        "id": "21QaGoGZj1kN",
        "outputId": "b8b0cade-f2dc-44a6-a662-17ee615d51de"
      },
      "execution_count": null,
      "outputs": [
        {
          "output_type": "stream",
          "name": "stderr",
          "text": [
            "/usr/local/lib/python3.10/dist-packages/fuzzywuzzy/fuzz.py:11: UserWarning: Using slow pure-python SequenceMatcher. Install python-Levenshtein to remove this warning\n",
            "  warnings.warn('Using slow pure-python SequenceMatcher. Install python-Levenshtein to remove this warning')\n"
          ]
        }
      ]
    },
    {
      "cell_type": "code",
      "source": [
        "df_income_zipcode = pd.read_csv('/content/drive/MyDrive/Hackathons/4 5 24/Datasets/Transportation Data April 5/IRSIncomeByZipCode.csv')\n",
        "df_rt_bus = pd.read_csv('/content/drive/MyDrive/Hackathons/4 5 24/Datasets/Transportation Data April 5/Regional_Transportation_Authority_Bus_Stops_20240402.csv')\n",
        "df_weGo_bus = pd.read_csv('/content/drive/MyDrive/Hackathons/4 5 24/Datasets/Transportation Data April 5/WeGo_Transit_Bus_Stops_20240402.csv')\n",
        "df_SDoH = pd.read_csv('/content/drive/MyDrive/Hackathons/4 5 24/Datasets/Transportation Data April 5/SDoH_TN_zipcode_2015-2020.csv')"
      ],
      "metadata": {
        "id": "gJlzSD0rjyYr"
      },
      "execution_count": null,
      "outputs": []
    },
    {
      "cell_type": "code",
      "execution_count": null,
      "metadata": {
        "colab": {
          "base_uri": "https://localhost:8080/"
        },
        "id": "YdJC2df9Dt-Z",
        "outputId": "4a64e181-d59c-4d37-be0d-e526a1ff1605"
      },
      "outputs": [
        {
          "output_type": "stream",
          "name": "stdout",
          "text": [
            "init 2578\n",
            "end 2524\n"
          ]
        }
      ],
      "source": [
        "print(\"init\",len(df_weGo_bus))\n",
        "df_dropedNa = df_weGo_bus.dropna(subset=['Mapped Location'])\n",
        "print(\"end\",len(df_dropedNa))\n",
        "\n",
        "data = df_dropedNa['Mapped Location'].str.strip('()').str.split(',').str[:2]\n",
        "data.head()\n",
        "geom = pd.DataFrame(data.tolist(), columns=['lat', 'long'], index=df_dropedNa.index) \\\n",
        "         .apply(pd.to_numeric, errors='coerce')\n",
        "df_filteredLatLon = df_dropedNa.join(geom)"
      ]
    },
    {
      "cell_type": "code",
      "source": [
        "def getZipCode(lat, lon):\n",
        "  try:\n",
        "    search = SearchEngine()\n",
        "    result = search.by_coordinates(lat=lat,lng=lon, returns=1)\n",
        "    return result[0].zipcode\n",
        "  except:\n",
        "    return 'Nan'"
      ],
      "metadata": {
        "id": "rAMuzPApjs7o"
      },
      "execution_count": null,
      "outputs": []
    },
    {
      "cell_type": "code",
      "source": [
        "zipCodes = []\n",
        "for i,row in df_filteredLatLon.iterrows():\n",
        "    zipCodes += [getZipCode(row['lat'],row['long'])]\n",
        "\n",
        "df_filteredLatLon['ZipCodes'] = zipCodes\n",
        "df_filteredLatLon['ZipCodes'].value_counts()"
      ],
      "metadata": {
        "colab": {
          "base_uri": "https://localhost:8080/"
        },
        "id": "iqX7I7TVDxGO",
        "outputId": "4a7c6d8b-479d-4d65-f362-08853d73872e"
      },
      "execution_count": null,
      "outputs": [
        {
          "output_type": "stream",
          "name": "stdout",
          "text": [
            "Download /root/.uszipcode/simple_db.sqlite from https://github.com/MacHu-GWU/uszipcode-project/releases/download/1.0.1.db/simple_db.sqlite ...\n",
            "  1.00 MB downloaded ...\n",
            "  2.00 MB downloaded ...\n",
            "  3.00 MB downloaded ...\n",
            "  4.00 MB downloaded ...\n",
            "  5.00 MB downloaded ...\n",
            "  6.00 MB downloaded ...\n",
            "  7.00 MB downloaded ...\n",
            "  8.00 MB downloaded ...\n",
            "  9.00 MB downloaded ...\n",
            "  10.00 MB downloaded ...\n",
            "  11.00 MB downloaded ...\n",
            "  Complete!\n"
          ]
        },
        {
          "output_type": "stream",
          "name": "stderr",
          "text": [
            "Exception ignored in: <function SearchEngine.__del__ at 0x7f20f03b53f0>\n",
            "Traceback (most recent call last):\n",
            "  File \"/usr/local/lib/python3.10/dist-packages/uszipcode/search.py\", line 196, in __del__\n",
            "    self.close()\n",
            "  File \"/usr/local/lib/python3.10/dist-packages/uszipcode/search.py\", line 202, in close\n",
            "    self.ses.close()\n",
            "  File \"/usr/local/lib/python3.10/dist-packages/sqlalchemy/orm/session.py\", line 1816, in close\n",
            "    self._close_impl(invalidate=False)\n",
            "  File \"/usr/local/lib/python3.10/dist-packages/sqlalchemy/orm/session.py\", line 1858, in _close_impl\n",
            "    transaction.close(invalidate)\n",
            "  File \"/usr/local/lib/python3.10/dist-packages/sqlalchemy/orm/session.py\", line 926, in close\n",
            "    transaction.close()\n",
            "  File \"/usr/local/lib/python3.10/dist-packages/sqlalchemy/engine/base.py\", line 2426, in close\n",
            "    self._do_close()\n",
            "  File \"/usr/local/lib/python3.10/dist-packages/sqlalchemy/engine/base.py\", line 2649, in _do_close\n",
            "    self._close_impl()\n",
            "  File \"/usr/local/lib/python3.10/dist-packages/sqlalchemy/engine/base.py\", line 2635, in _close_impl\n",
            "    self._connection_rollback_impl()\n",
            "  File \"/usr/local/lib/python3.10/dist-packages/sqlalchemy/engine/base.py\", line 2627, in _connection_rollback_impl\n",
            "    self.connection._rollback_impl()\n",
            "  File \"/usr/local/lib/python3.10/dist-packages/sqlalchemy/engine/base.py\", line 1064, in _rollback_impl\n",
            "    self._handle_dbapi_exception(e, None, None, None, None)\n",
            "  File \"/usr/local/lib/python3.10/dist-packages/sqlalchemy/engine/base.py\", line 2134, in _handle_dbapi_exception\n",
            "    util.raise_(\n",
            "  File \"/usr/local/lib/python3.10/dist-packages/sqlalchemy/util/compat.py\", line 211, in raise_\n",
            "    raise exception\n",
            "  File \"/usr/local/lib/python3.10/dist-packages/sqlalchemy/engine/base.py\", line 1062, in _rollback_impl\n",
            "    self.engine.dialect.do_rollback(self.connection)\n",
            "  File \"/usr/local/lib/python3.10/dist-packages/sqlalchemy/engine/default.py\", line 683, in do_rollback\n",
            "    dbapi_connection.rollback()\n",
            "sqlalchemy.exc.ProgrammingError: (sqlite3.ProgrammingError) SQLite objects created in a thread can only be used in that same thread. The object was created in thread id 139780940554240 and this is thread id 139780480284224.\n",
            "(Background on this error at: https://sqlalche.me/e/14/f405)\n",
            "Exception ignored in: <function SearchEngine.__del__ at 0x7f20f03b53f0>\n",
            "Traceback (most recent call last):\n",
            "  File \"/usr/local/lib/python3.10/dist-packages/uszipcode/search.py\", line 196, in __del__\n",
            "    self.close()\n",
            "  File \"/usr/local/lib/python3.10/dist-packages/uszipcode/search.py\", line 202, in close\n",
            "    self.ses.close()\n",
            "  File \"/usr/local/lib/python3.10/dist-packages/sqlalchemy/orm/session.py\", line 1816, in close\n",
            "    self._close_impl(invalidate=False)\n",
            "  File \"/usr/local/lib/python3.10/dist-packages/sqlalchemy/orm/session.py\", line 1858, in _close_impl\n",
            "    transaction.close(invalidate)\n",
            "  File \"/usr/local/lib/python3.10/dist-packages/sqlalchemy/orm/session.py\", line 926, in close\n",
            "    transaction.close()\n",
            "  File \"/usr/local/lib/python3.10/dist-packages/sqlalchemy/engine/base.py\", line 2426, in close\n",
            "    self._do_close()\n",
            "  File \"/usr/local/lib/python3.10/dist-packages/sqlalchemy/engine/base.py\", line 2649, in _do_close\n",
            "    self._close_impl()\n",
            "  File \"/usr/local/lib/python3.10/dist-packages/sqlalchemy/engine/base.py\", line 2635, in _close_impl\n",
            "    self._connection_rollback_impl()\n",
            "  File \"/usr/local/lib/python3.10/dist-packages/sqlalchemy/engine/base.py\", line 2627, in _connection_rollback_impl\n",
            "    self.connection._rollback_impl()\n",
            "  File \"/usr/local/lib/python3.10/dist-packages/sqlalchemy/engine/base.py\", line 1064, in _rollback_impl\n",
            "    self._handle_dbapi_exception(e, None, None, None, None)\n",
            "  File \"/usr/local/lib/python3.10/dist-packages/sqlalchemy/engine/base.py\", line 2134, in _handle_dbapi_exception\n",
            "    util.raise_(\n",
            "  File \"/usr/local/lib/python3.10/dist-packages/sqlalchemy/util/compat.py\", line 211, in raise_\n",
            "    raise exception\n",
            "  File \"/usr/local/lib/python3.10/dist-packages/sqlalchemy/engine/base.py\", line 1062, in _rollback_impl\n",
            "    self.engine.dialect.do_rollback(self.connection)\n",
            "  File \"/usr/local/lib/python3.10/dist-packages/sqlalchemy/engine/default.py\", line 683, in do_rollback\n",
            "    dbapi_connection.rollback()\n",
            "sqlalchemy.exc.ProgrammingError: (sqlite3.ProgrammingError) SQLite objects created in a thread can only be used in that same thread. The object was created in thread id 139780940554240 and this is thread id 139780480284224.\n",
            "(Background on this error at: https://sqlalche.me/e/14/f405)\n",
            "Exception ignored in: <function SearchEngine.__del__ at 0x7f20f03b53f0>\n",
            "Traceback (most recent call last):\n",
            "  File \"/usr/local/lib/python3.10/dist-packages/uszipcode/search.py\", line 196, in __del__\n",
            "    self.close()\n",
            "  File \"/usr/local/lib/python3.10/dist-packages/uszipcode/search.py\", line 202, in close\n",
            "    self.ses.close()\n",
            "  File \"/usr/local/lib/python3.10/dist-packages/sqlalchemy/orm/session.py\", line 1816, in close\n",
            "    self._close_impl(invalidate=False)\n",
            "  File \"/usr/local/lib/python3.10/dist-packages/sqlalchemy/orm/session.py\", line 1858, in _close_impl\n",
            "    transaction.close(invalidate)\n",
            "  File \"/usr/local/lib/python3.10/dist-packages/sqlalchemy/orm/session.py\", line 926, in close\n",
            "    transaction.close()\n",
            "  File \"/usr/local/lib/python3.10/dist-packages/sqlalchemy/engine/base.py\", line 2426, in close\n",
            "    self._do_close()\n",
            "  File \"/usr/local/lib/python3.10/dist-packages/sqlalchemy/engine/base.py\", line 2649, in _do_close\n",
            "    self._close_impl()\n",
            "  File \"/usr/local/lib/python3.10/dist-packages/sqlalchemy/engine/base.py\", line 2635, in _close_impl\n",
            "    self._connection_rollback_impl()\n",
            "  File \"/usr/local/lib/python3.10/dist-packages/sqlalchemy/engine/base.py\", line 2627, in _connection_rollback_impl\n",
            "    self.connection._rollback_impl()\n",
            "  File \"/usr/local/lib/python3.10/dist-packages/sqlalchemy/engine/base.py\", line 1064, in _rollback_impl\n",
            "    self._handle_dbapi_exception(e, None, None, None, None)\n",
            "  File \"/usr/local/lib/python3.10/dist-packages/sqlalchemy/engine/base.py\", line 2134, in _handle_dbapi_exception\n",
            "    util.raise_(\n",
            "  File \"/usr/local/lib/python3.10/dist-packages/sqlalchemy/util/compat.py\", line 211, in raise_\n",
            "    raise exception\n",
            "  File \"/usr/local/lib/python3.10/dist-packages/sqlalchemy/engine/base.py\", line 1062, in _rollback_impl\n",
            "    self.engine.dialect.do_rollback(self.connection)\n",
            "  File \"/usr/local/lib/python3.10/dist-packages/sqlalchemy/engine/default.py\", line 683, in do_rollback\n",
            "    dbapi_connection.rollback()\n",
            "sqlalchemy.exc.ProgrammingError: (sqlite3.ProgrammingError) SQLite objects created in a thread can only be used in that same thread. The object was created in thread id 139780940554240 and this is thread id 139780480284224.\n",
            "(Background on this error at: https://sqlalche.me/e/14/f405)\n",
            "Exception ignored in: <function SearchEngine.__del__ at 0x7f20f03b53f0>\n",
            "Traceback (most recent call last):\n",
            "  File \"/usr/local/lib/python3.10/dist-packages/uszipcode/search.py\", line 196, in __del__\n",
            "    self.close()\n",
            "  File \"/usr/local/lib/python3.10/dist-packages/uszipcode/search.py\", line 202, in close\n",
            "    self.ses.close()\n",
            "  File \"/usr/local/lib/python3.10/dist-packages/sqlalchemy/orm/session.py\", line 1816, in close\n",
            "    self._close_impl(invalidate=False)\n",
            "  File \"/usr/local/lib/python3.10/dist-packages/sqlalchemy/orm/session.py\", line 1858, in _close_impl\n",
            "    transaction.close(invalidate)\n",
            "  File \"/usr/local/lib/python3.10/dist-packages/sqlalchemy/orm/session.py\", line 926, in close\n",
            "    transaction.close()\n",
            "  File \"/usr/local/lib/python3.10/dist-packages/sqlalchemy/engine/base.py\", line 2426, in close\n",
            "    self._do_close()\n",
            "  File \"/usr/local/lib/python3.10/dist-packages/sqlalchemy/engine/base.py\", line 2649, in _do_close\n",
            "    self._close_impl()\n",
            "  File \"/usr/local/lib/python3.10/dist-packages/sqlalchemy/engine/base.py\", line 2635, in _close_impl\n",
            "    self._connection_rollback_impl()\n",
            "  File \"/usr/local/lib/python3.10/dist-packages/sqlalchemy/engine/base.py\", line 2627, in _connection_rollback_impl\n",
            "    self.connection._rollback_impl()\n",
            "  File \"/usr/local/lib/python3.10/dist-packages/sqlalchemy/engine/base.py\", line 1064, in _rollback_impl\n",
            "    self._handle_dbapi_exception(e, None, None, None, None)\n",
            "  File \"/usr/local/lib/python3.10/dist-packages/sqlalchemy/engine/base.py\", line 2134, in _handle_dbapi_exception\n",
            "    util.raise_(\n",
            "  File \"/usr/local/lib/python3.10/dist-packages/sqlalchemy/util/compat.py\", line 211, in raise_\n",
            "    raise exception\n",
            "  File \"/usr/local/lib/python3.10/dist-packages/sqlalchemy/engine/base.py\", line 1062, in _rollback_impl\n",
            "    self.engine.dialect.do_rollback(self.connection)\n",
            "  File \"/usr/local/lib/python3.10/dist-packages/sqlalchemy/engine/default.py\", line 683, in do_rollback\n",
            "    dbapi_connection.rollback()\n",
            "sqlalchemy.exc.ProgrammingError: (sqlite3.ProgrammingError) SQLite objects created in a thread can only be used in that same thread. The object was created in thread id 139780940554240 and this is thread id 139780480284224.\n",
            "(Background on this error at: https://sqlalche.me/e/14/f405)\n",
            "Exception ignored in: <function SearchEngine.__del__ at 0x7f20f03b53f0>\n",
            "Traceback (most recent call last):\n",
            "  File \"/usr/local/lib/python3.10/dist-packages/uszipcode/search.py\", line 196, in __del__\n",
            "    self.close()\n",
            "  File \"/usr/local/lib/python3.10/dist-packages/uszipcode/search.py\", line 202, in close\n",
            "    self.ses.close()\n",
            "  File \"/usr/local/lib/python3.10/dist-packages/sqlalchemy/orm/session.py\", line 1816, in close\n",
            "    self._close_impl(invalidate=False)\n",
            "  File \"/usr/local/lib/python3.10/dist-packages/sqlalchemy/orm/session.py\", line 1858, in _close_impl\n",
            "    transaction.close(invalidate)\n",
            "  File \"/usr/local/lib/python3.10/dist-packages/sqlalchemy/orm/session.py\", line 926, in close\n",
            "    transaction.close()\n",
            "  File \"/usr/local/lib/python3.10/dist-packages/sqlalchemy/engine/base.py\", line 2426, in close\n",
            "    self._do_close()\n",
            "  File \"/usr/local/lib/python3.10/dist-packages/sqlalchemy/engine/base.py\", line 2649, in _do_close\n",
            "    self._close_impl()\n",
            "  File \"/usr/local/lib/python3.10/dist-packages/sqlalchemy/engine/base.py\", line 2635, in _close_impl\n",
            "    self._connection_rollback_impl()\n",
            "  File \"/usr/local/lib/python3.10/dist-packages/sqlalchemy/engine/base.py\", line 2627, in _connection_rollback_impl\n",
            "    self.connection._rollback_impl()\n",
            "  File \"/usr/local/lib/python3.10/dist-packages/sqlalchemy/engine/base.py\", line 1064, in _rollback_impl\n",
            "    self._handle_dbapi_exception(e, None, None, None, None)\n",
            "  File \"/usr/local/lib/python3.10/dist-packages/sqlalchemy/engine/base.py\", line 2134, in _handle_dbapi_exception\n",
            "    util.raise_(\n",
            "  File \"/usr/local/lib/python3.10/dist-packages/sqlalchemy/util/compat.py\", line 211, in raise_\n",
            "    raise exception\n",
            "  File \"/usr/local/lib/python3.10/dist-packages/sqlalchemy/engine/base.py\", line 1062, in _rollback_impl\n",
            "    self.engine.dialect.do_rollback(self.connection)\n",
            "  File \"/usr/local/lib/python3.10/dist-packages/sqlalchemy/engine/default.py\", line 683, in do_rollback\n",
            "    dbapi_connection.rollback()\n",
            "sqlalchemy.exc.ProgrammingError: (sqlite3.ProgrammingError) SQLite objects created in a thread can only be used in that same thread. The object was created in thread id 139780940554240 and this is thread id 139780480284224.\n",
            "(Background on this error at: https://sqlalche.me/e/14/f405)\n",
            "Exception ignored in: <function SearchEngine.__del__ at 0x7f20f03b53f0>\n",
            "Traceback (most recent call last):\n",
            "  File \"/usr/local/lib/python3.10/dist-packages/uszipcode/search.py\", line 196, in __del__\n",
            "    self.close()\n",
            "  File \"/usr/local/lib/python3.10/dist-packages/uszipcode/search.py\", line 202, in close\n",
            "    self.ses.close()\n",
            "  File \"/usr/local/lib/python3.10/dist-packages/sqlalchemy/orm/session.py\", line 1816, in close\n",
            "    self._close_impl(invalidate=False)\n",
            "  File \"/usr/local/lib/python3.10/dist-packages/sqlalchemy/orm/session.py\", line 1858, in _close_impl\n",
            "    transaction.close(invalidate)\n",
            "  File \"/usr/local/lib/python3.10/dist-packages/sqlalchemy/orm/session.py\", line 926, in close\n",
            "    transaction.close()\n",
            "  File \"/usr/local/lib/python3.10/dist-packages/sqlalchemy/engine/base.py\", line 2426, in close\n",
            "    self._do_close()\n",
            "  File \"/usr/local/lib/python3.10/dist-packages/sqlalchemy/engine/base.py\", line 2649, in _do_close\n",
            "    self._close_impl()\n",
            "  File \"/usr/local/lib/python3.10/dist-packages/sqlalchemy/engine/base.py\", line 2635, in _close_impl\n",
            "    self._connection_rollback_impl()\n",
            "  File \"/usr/local/lib/python3.10/dist-packages/sqlalchemy/engine/base.py\", line 2627, in _connection_rollback_impl\n",
            "    self.connection._rollback_impl()\n",
            "  File \"/usr/local/lib/python3.10/dist-packages/sqlalchemy/engine/base.py\", line 1064, in _rollback_impl\n",
            "    self._handle_dbapi_exception(e, None, None, None, None)\n",
            "  File \"/usr/local/lib/python3.10/dist-packages/sqlalchemy/engine/base.py\", line 2134, in _handle_dbapi_exception\n",
            "    util.raise_(\n",
            "  File \"/usr/local/lib/python3.10/dist-packages/sqlalchemy/util/compat.py\", line 211, in raise_\n",
            "    raise exception\n",
            "  File \"/usr/local/lib/python3.10/dist-packages/sqlalchemy/engine/base.py\", line 1062, in _rollback_impl\n",
            "    self.engine.dialect.do_rollback(self.connection)\n",
            "  File \"/usr/local/lib/python3.10/dist-packages/sqlalchemy/engine/default.py\", line 683, in do_rollback\n",
            "    dbapi_connection.rollback()\n",
            "sqlalchemy.exc.ProgrammingError: (sqlite3.ProgrammingError) SQLite objects created in a thread can only be used in that same thread. The object was created in thread id 139780940554240 and this is thread id 139780480284224.\n",
            "(Background on this error at: https://sqlalche.me/e/14/f405)\n",
            "Exception ignored in: <function SearchEngine.__del__ at 0x7f20f03b53f0>\n",
            "Traceback (most recent call last):\n",
            "  File \"/usr/local/lib/python3.10/dist-packages/uszipcode/search.py\", line 196, in __del__\n",
            "    self.close()\n",
            "  File \"/usr/local/lib/python3.10/dist-packages/uszipcode/search.py\", line 202, in close\n",
            "    self.ses.close()\n",
            "  File \"/usr/local/lib/python3.10/dist-packages/sqlalchemy/orm/session.py\", line 1816, in close\n",
            "    self._close_impl(invalidate=False)\n",
            "  File \"/usr/local/lib/python3.10/dist-packages/sqlalchemy/orm/session.py\", line 1858, in _close_impl\n",
            "    transaction.close(invalidate)\n",
            "  File \"/usr/local/lib/python3.10/dist-packages/sqlalchemy/orm/session.py\", line 926, in close\n",
            "    transaction.close()\n",
            "  File \"/usr/local/lib/python3.10/dist-packages/sqlalchemy/engine/base.py\", line 2426, in close\n",
            "    self._do_close()\n",
            "  File \"/usr/local/lib/python3.10/dist-packages/sqlalchemy/engine/base.py\", line 2649, in _do_close\n",
            "    self._close_impl()\n",
            "  File \"/usr/local/lib/python3.10/dist-packages/sqlalchemy/engine/base.py\", line 2635, in _close_impl\n",
            "    self._connection_rollback_impl()\n",
            "  File \"/usr/local/lib/python3.10/dist-packages/sqlalchemy/engine/base.py\", line 2627, in _connection_rollback_impl\n",
            "    self.connection._rollback_impl()\n",
            "  File \"/usr/local/lib/python3.10/dist-packages/sqlalchemy/engine/base.py\", line 1064, in _rollback_impl\n",
            "    self._handle_dbapi_exception(e, None, None, None, None)\n",
            "  File \"/usr/local/lib/python3.10/dist-packages/sqlalchemy/engine/base.py\", line 2134, in _handle_dbapi_exception\n",
            "    util.raise_(\n",
            "  File \"/usr/local/lib/python3.10/dist-packages/sqlalchemy/util/compat.py\", line 211, in raise_\n",
            "    raise exception\n",
            "  File \"/usr/local/lib/python3.10/dist-packages/sqlalchemy/engine/base.py\", line 1062, in _rollback_impl\n",
            "    self.engine.dialect.do_rollback(self.connection)\n",
            "  File \"/usr/local/lib/python3.10/dist-packages/sqlalchemy/engine/default.py\", line 683, in do_rollback\n",
            "    dbapi_connection.rollback()\n",
            "sqlalchemy.exc.ProgrammingError: (sqlite3.ProgrammingError) SQLite objects created in a thread can only be used in that same thread. The object was created in thread id 139780940554240 and this is thread id 139780480284224.\n",
            "(Background on this error at: https://sqlalche.me/e/14/f405)\n",
            "Exception ignored in: <function SearchEngine.__del__ at 0x7f20f03b53f0>\n",
            "Traceback (most recent call last):\n",
            "  File \"/usr/local/lib/python3.10/dist-packages/uszipcode/search.py\", line 196, in __del__\n",
            "    self.close()\n",
            "  File \"/usr/local/lib/python3.10/dist-packages/uszipcode/search.py\", line 202, in close\n",
            "    self.ses.close()\n",
            "  File \"/usr/local/lib/python3.10/dist-packages/sqlalchemy/orm/session.py\", line 1816, in close\n",
            "    self._close_impl(invalidate=False)\n",
            "  File \"/usr/local/lib/python3.10/dist-packages/sqlalchemy/orm/session.py\", line 1858, in _close_impl\n",
            "    transaction.close(invalidate)\n",
            "  File \"/usr/local/lib/python3.10/dist-packages/sqlalchemy/orm/session.py\", line 926, in close\n",
            "    transaction.close()\n",
            "  File \"/usr/local/lib/python3.10/dist-packages/sqlalchemy/engine/base.py\", line 2426, in close\n",
            "    self._do_close()\n",
            "  File \"/usr/local/lib/python3.10/dist-packages/sqlalchemy/engine/base.py\", line 2649, in _do_close\n",
            "    self._close_impl()\n",
            "  File \"/usr/local/lib/python3.10/dist-packages/sqlalchemy/engine/base.py\", line 2635, in _close_impl\n",
            "    self._connection_rollback_impl()\n",
            "  File \"/usr/local/lib/python3.10/dist-packages/sqlalchemy/engine/base.py\", line 2627, in _connection_rollback_impl\n",
            "    self.connection._rollback_impl()\n",
            "  File \"/usr/local/lib/python3.10/dist-packages/sqlalchemy/engine/base.py\", line 1064, in _rollback_impl\n",
            "    self._handle_dbapi_exception(e, None, None, None, None)\n",
            "  File \"/usr/local/lib/python3.10/dist-packages/sqlalchemy/engine/base.py\", line 2134, in _handle_dbapi_exception\n",
            "    util.raise_(\n",
            "  File \"/usr/local/lib/python3.10/dist-packages/sqlalchemy/util/compat.py\", line 211, in raise_\n",
            "    raise exception\n",
            "  File \"/usr/local/lib/python3.10/dist-packages/sqlalchemy/engine/base.py\", line 1062, in _rollback_impl\n",
            "    self.engine.dialect.do_rollback(self.connection)\n",
            "  File \"/usr/local/lib/python3.10/dist-packages/sqlalchemy/engine/default.py\", line 683, in do_rollback\n",
            "    dbapi_connection.rollback()\n",
            "sqlalchemy.exc.ProgrammingError: (sqlite3.ProgrammingError) SQLite objects created in a thread can only be used in that same thread. The object was created in thread id 139780940554240 and this is thread id 139780480284224.\n",
            "(Background on this error at: https://sqlalche.me/e/14/f405)\n",
            "Exception ignored in: <function SearchEngine.__del__ at 0x7f20f03b53f0>\n",
            "Traceback (most recent call last):\n",
            "  File \"/usr/local/lib/python3.10/dist-packages/uszipcode/search.py\", line 196, in __del__\n",
            "    self.close()\n",
            "  File \"/usr/local/lib/python3.10/dist-packages/uszipcode/search.py\", line 202, in close\n",
            "    self.ses.close()\n",
            "  File \"/usr/local/lib/python3.10/dist-packages/sqlalchemy/orm/session.py\", line 1816, in close\n",
            "    self._close_impl(invalidate=False)\n",
            "  File \"/usr/local/lib/python3.10/dist-packages/sqlalchemy/orm/session.py\", line 1858, in _close_impl\n",
            "    transaction.close(invalidate)\n",
            "  File \"/usr/local/lib/python3.10/dist-packages/sqlalchemy/orm/session.py\", line 926, in close\n",
            "    transaction.close()\n",
            "  File \"/usr/local/lib/python3.10/dist-packages/sqlalchemy/engine/base.py\", line 2426, in close\n",
            "    self._do_close()\n",
            "  File \"/usr/local/lib/python3.10/dist-packages/sqlalchemy/engine/base.py\", line 2649, in _do_close\n",
            "    self._close_impl()\n",
            "  File \"/usr/local/lib/python3.10/dist-packages/sqlalchemy/engine/base.py\", line 2635, in _close_impl\n",
            "    self._connection_rollback_impl()\n",
            "  File \"/usr/local/lib/python3.10/dist-packages/sqlalchemy/engine/base.py\", line 2627, in _connection_rollback_impl\n",
            "    self.connection._rollback_impl()\n",
            "  File \"/usr/local/lib/python3.10/dist-packages/sqlalchemy/engine/base.py\", line 1064, in _rollback_impl\n",
            "    self._handle_dbapi_exception(e, None, None, None, None)\n",
            "  File \"/usr/local/lib/python3.10/dist-packages/sqlalchemy/engine/base.py\", line 2134, in _handle_dbapi_exception\n",
            "    util.raise_(\n",
            "  File \"/usr/local/lib/python3.10/dist-packages/sqlalchemy/util/compat.py\", line 211, in raise_\n",
            "    raise exception\n",
            "  File \"/usr/local/lib/python3.10/dist-packages/sqlalchemy/engine/base.py\", line 1062, in _rollback_impl\n",
            "    self.engine.dialect.do_rollback(self.connection)\n",
            "  File \"/usr/local/lib/python3.10/dist-packages/sqlalchemy/engine/default.py\", line 683, in do_rollback\n",
            "    dbapi_connection.rollback()\n",
            "sqlalchemy.exc.ProgrammingError: (sqlite3.ProgrammingError) SQLite objects created in a thread can only be used in that same thread. The object was created in thread id 139780940554240 and this is thread id 139780480284224.\n",
            "(Background on this error at: https://sqlalche.me/e/14/f405)\n",
            "Exception ignored in: <function SearchEngine.__del__ at 0x7f20f03b53f0>\n",
            "Traceback (most recent call last):\n",
            "  File \"/usr/local/lib/python3.10/dist-packages/uszipcode/search.py\", line 196, in __del__\n",
            "    self.close()\n",
            "  File \"/usr/local/lib/python3.10/dist-packages/uszipcode/search.py\", line 202, in close\n",
            "    self.ses.close()\n",
            "  File \"/usr/local/lib/python3.10/dist-packages/sqlalchemy/orm/session.py\", line 1816, in close\n",
            "    self._close_impl(invalidate=False)\n",
            "  File \"/usr/local/lib/python3.10/dist-packages/sqlalchemy/orm/session.py\", line 1858, in _close_impl\n",
            "    transaction.close(invalidate)\n",
            "  File \"/usr/local/lib/python3.10/dist-packages/sqlalchemy/orm/session.py\", line 926, in close\n",
            "    transaction.close()\n",
            "  File \"/usr/local/lib/python3.10/dist-packages/sqlalchemy/engine/base.py\", line 2426, in close\n",
            "    self._do_close()\n",
            "  File \"/usr/local/lib/python3.10/dist-packages/sqlalchemy/engine/base.py\", line 2649, in _do_close\n",
            "    self._close_impl()\n",
            "  File \"/usr/local/lib/python3.10/dist-packages/sqlalchemy/engine/base.py\", line 2635, in _close_impl\n",
            "    self._connection_rollback_impl()\n",
            "  File \"/usr/local/lib/python3.10/dist-packages/sqlalchemy/engine/base.py\", line 2627, in _connection_rollback_impl\n",
            "    self.connection._rollback_impl()\n",
            "  File \"/usr/local/lib/python3.10/dist-packages/sqlalchemy/engine/base.py\", line 1064, in _rollback_impl\n",
            "    self._handle_dbapi_exception(e, None, None, None, None)\n",
            "  File \"/usr/local/lib/python3.10/dist-packages/sqlalchemy/engine/base.py\", line 2134, in _handle_dbapi_exception\n",
            "    util.raise_(\n",
            "  File \"/usr/local/lib/python3.10/dist-packages/sqlalchemy/util/compat.py\", line 211, in raise_\n",
            "    raise exception\n",
            "  File \"/usr/local/lib/python3.10/dist-packages/sqlalchemy/engine/base.py\", line 1062, in _rollback_impl\n",
            "    self.engine.dialect.do_rollback(self.connection)\n",
            "  File \"/usr/local/lib/python3.10/dist-packages/sqlalchemy/engine/default.py\", line 683, in do_rollback\n",
            "    dbapi_connection.rollback()\n",
            "sqlalchemy.exc.ProgrammingError: (sqlite3.ProgrammingError) SQLite objects created in a thread can only be used in that same thread. The object was created in thread id 139780940554240 and this is thread id 139780480284224.\n",
            "(Background on this error at: https://sqlalche.me/e/14/f405)\n",
            "Exception ignored in: <function SearchEngine.__del__ at 0x7f20f03b53f0>\n",
            "Traceback (most recent call last):\n",
            "  File \"/usr/local/lib/python3.10/dist-packages/uszipcode/search.py\", line 196, in __del__\n",
            "    self.close()\n",
            "  File \"/usr/local/lib/python3.10/dist-packages/uszipcode/search.py\", line 202, in close\n",
            "    self.ses.close()\n",
            "  File \"/usr/local/lib/python3.10/dist-packages/sqlalchemy/orm/session.py\", line 1816, in close\n",
            "    self._close_impl(invalidate=False)\n",
            "  File \"/usr/local/lib/python3.10/dist-packages/sqlalchemy/orm/session.py\", line 1858, in _close_impl\n",
            "    transaction.close(invalidate)\n",
            "  File \"/usr/local/lib/python3.10/dist-packages/sqlalchemy/orm/session.py\", line 926, in close\n",
            "    transaction.close()\n",
            "  File \"/usr/local/lib/python3.10/dist-packages/sqlalchemy/engine/base.py\", line 2426, in close\n",
            "    self._do_close()\n",
            "  File \"/usr/local/lib/python3.10/dist-packages/sqlalchemy/engine/base.py\", line 2649, in _do_close\n",
            "    self._close_impl()\n",
            "  File \"/usr/local/lib/python3.10/dist-packages/sqlalchemy/engine/base.py\", line 2635, in _close_impl\n",
            "    self._connection_rollback_impl()\n",
            "  File \"/usr/local/lib/python3.10/dist-packages/sqlalchemy/engine/base.py\", line 2627, in _connection_rollback_impl\n",
            "    self.connection._rollback_impl()\n",
            "  File \"/usr/local/lib/python3.10/dist-packages/sqlalchemy/engine/base.py\", line 1064, in _rollback_impl\n",
            "    self._handle_dbapi_exception(e, None, None, None, None)\n",
            "  File \"/usr/local/lib/python3.10/dist-packages/sqlalchemy/engine/base.py\", line 2134, in _handle_dbapi_exception\n",
            "    util.raise_(\n",
            "  File \"/usr/local/lib/python3.10/dist-packages/sqlalchemy/util/compat.py\", line 211, in raise_\n",
            "    raise exception\n",
            "  File \"/usr/local/lib/python3.10/dist-packages/sqlalchemy/engine/base.py\", line 1062, in _rollback_impl\n",
            "    self.engine.dialect.do_rollback(self.connection)\n",
            "  File \"/usr/local/lib/python3.10/dist-packages/sqlalchemy/engine/default.py\", line 683, in do_rollback\n",
            "    dbapi_connection.rollback()\n",
            "sqlalchemy.exc.ProgrammingError: (sqlite3.ProgrammingError) SQLite objects created in a thread can only be used in that same thread. The object was created in thread id 139780940554240 and this is thread id 139780480284224.\n",
            "(Background on this error at: https://sqlalche.me/e/14/f405)\n",
            "Exception ignored in: <function SearchEngine.__del__ at 0x7f20f03b53f0>\n",
            "Traceback (most recent call last):\n",
            "  File \"/usr/local/lib/python3.10/dist-packages/uszipcode/search.py\", line 196, in __del__\n",
            "    self.close()\n",
            "  File \"/usr/local/lib/python3.10/dist-packages/uszipcode/search.py\", line 202, in close\n",
            "    self.ses.close()\n",
            "  File \"/usr/local/lib/python3.10/dist-packages/sqlalchemy/orm/session.py\", line 1816, in close\n",
            "    self._close_impl(invalidate=False)\n",
            "  File \"/usr/local/lib/python3.10/dist-packages/sqlalchemy/orm/session.py\", line 1858, in _close_impl\n",
            "    transaction.close(invalidate)\n",
            "  File \"/usr/local/lib/python3.10/dist-packages/sqlalchemy/orm/session.py\", line 926, in close\n",
            "    transaction.close()\n",
            "  File \"/usr/local/lib/python3.10/dist-packages/sqlalchemy/engine/base.py\", line 2426, in close\n",
            "    self._do_close()\n",
            "  File \"/usr/local/lib/python3.10/dist-packages/sqlalchemy/engine/base.py\", line 2649, in _do_close\n",
            "    self._close_impl()\n",
            "  File \"/usr/local/lib/python3.10/dist-packages/sqlalchemy/engine/base.py\", line 2635, in _close_impl\n",
            "    self._connection_rollback_impl()\n",
            "  File \"/usr/local/lib/python3.10/dist-packages/sqlalchemy/engine/base.py\", line 2627, in _connection_rollback_impl\n",
            "    self.connection._rollback_impl()\n",
            "  File \"/usr/local/lib/python3.10/dist-packages/sqlalchemy/engine/base.py\", line 1064, in _rollback_impl\n",
            "    self._handle_dbapi_exception(e, None, None, None, None)\n",
            "  File \"/usr/local/lib/python3.10/dist-packages/sqlalchemy/engine/base.py\", line 2134, in _handle_dbapi_exception\n",
            "    util.raise_(\n",
            "  File \"/usr/local/lib/python3.10/dist-packages/sqlalchemy/util/compat.py\", line 211, in raise_\n",
            "    raise exception\n",
            "  File \"/usr/local/lib/python3.10/dist-packages/sqlalchemy/engine/base.py\", line 1062, in _rollback_impl\n",
            "    self.engine.dialect.do_rollback(self.connection)\n",
            "  File \"/usr/local/lib/python3.10/dist-packages/sqlalchemy/engine/default.py\", line 683, in do_rollback\n",
            "    dbapi_connection.rollback()\n",
            "sqlalchemy.exc.ProgrammingError: (sqlite3.ProgrammingError) SQLite objects created in a thread can only be used in that same thread. The object was created in thread id 139780940554240 and this is thread id 139780480284224.\n",
            "(Background on this error at: https://sqlalche.me/e/14/f405)\n",
            "Exception ignored in: <function SearchEngine.__del__ at 0x7f20f03b53f0>\n",
            "Traceback (most recent call last):\n",
            "  File \"/usr/local/lib/python3.10/dist-packages/uszipcode/search.py\", line 196, in __del__\n",
            "    self.close()\n",
            "  File \"/usr/local/lib/python3.10/dist-packages/uszipcode/search.py\", line 202, in close\n",
            "    self.ses.close()\n",
            "  File \"/usr/local/lib/python3.10/dist-packages/sqlalchemy/orm/session.py\", line 1816, in close\n",
            "    self._close_impl(invalidate=False)\n",
            "  File \"/usr/local/lib/python3.10/dist-packages/sqlalchemy/orm/session.py\", line 1858, in _close_impl\n",
            "    transaction.close(invalidate)\n",
            "  File \"/usr/local/lib/python3.10/dist-packages/sqlalchemy/orm/session.py\", line 926, in close\n",
            "    transaction.close()\n",
            "  File \"/usr/local/lib/python3.10/dist-packages/sqlalchemy/engine/base.py\", line 2426, in close\n",
            "    self._do_close()\n",
            "  File \"/usr/local/lib/python3.10/dist-packages/sqlalchemy/engine/base.py\", line 2649, in _do_close\n",
            "    self._close_impl()\n",
            "  File \"/usr/local/lib/python3.10/dist-packages/sqlalchemy/engine/base.py\", line 2635, in _close_impl\n",
            "    self._connection_rollback_impl()\n",
            "  File \"/usr/local/lib/python3.10/dist-packages/sqlalchemy/engine/base.py\", line 2627, in _connection_rollback_impl\n",
            "    self.connection._rollback_impl()\n",
            "  File \"/usr/local/lib/python3.10/dist-packages/sqlalchemy/engine/base.py\", line 1064, in _rollback_impl\n",
            "    self._handle_dbapi_exception(e, None, None, None, None)\n",
            "  File \"/usr/local/lib/python3.10/dist-packages/sqlalchemy/engine/base.py\", line 2134, in _handle_dbapi_exception\n",
            "    util.raise_(\n",
            "  File \"/usr/local/lib/python3.10/dist-packages/sqlalchemy/util/compat.py\", line 211, in raise_\n",
            "    raise exception\n",
            "  File \"/usr/local/lib/python3.10/dist-packages/sqlalchemy/engine/base.py\", line 1062, in _rollback_impl\n",
            "    self.engine.dialect.do_rollback(self.connection)\n",
            "  File \"/usr/local/lib/python3.10/dist-packages/sqlalchemy/engine/default.py\", line 683, in do_rollback\n",
            "    dbapi_connection.rollback()\n",
            "sqlalchemy.exc.ProgrammingError: (sqlite3.ProgrammingError) SQLite objects created in a thread can only be used in that same thread. The object was created in thread id 139780940554240 and this is thread id 139780480284224.\n",
            "(Background on this error at: https://sqlalche.me/e/14/f405)\n",
            "Exception ignored in: <function SearchEngine.__del__ at 0x7f20f03b53f0>\n",
            "Traceback (most recent call last):\n",
            "  File \"/usr/local/lib/python3.10/dist-packages/uszipcode/search.py\", line 196, in __del__\n",
            "    self.close()\n",
            "  File \"/usr/local/lib/python3.10/dist-packages/uszipcode/search.py\", line 202, in close\n",
            "    self.ses.close()\n",
            "  File \"/usr/local/lib/python3.10/dist-packages/sqlalchemy/orm/session.py\", line 1816, in close\n",
            "    self._close_impl(invalidate=False)\n",
            "  File \"/usr/local/lib/python3.10/dist-packages/sqlalchemy/orm/session.py\", line 1858, in _close_impl\n",
            "    transaction.close(invalidate)\n",
            "  File \"/usr/local/lib/python3.10/dist-packages/sqlalchemy/orm/session.py\", line 926, in close\n",
            "    transaction.close()\n",
            "  File \"/usr/local/lib/python3.10/dist-packages/sqlalchemy/engine/base.py\", line 2426, in close\n",
            "    self._do_close()\n",
            "  File \"/usr/local/lib/python3.10/dist-packages/sqlalchemy/engine/base.py\", line 2649, in _do_close\n",
            "    self._close_impl()\n",
            "  File \"/usr/local/lib/python3.10/dist-packages/sqlalchemy/engine/base.py\", line 2635, in _close_impl\n",
            "    self._connection_rollback_impl()\n",
            "  File \"/usr/local/lib/python3.10/dist-packages/sqlalchemy/engine/base.py\", line 2627, in _connection_rollback_impl\n",
            "    self.connection._rollback_impl()\n",
            "  File \"/usr/local/lib/python3.10/dist-packages/sqlalchemy/engine/base.py\", line 1064, in _rollback_impl\n",
            "    self._handle_dbapi_exception(e, None, None, None, None)\n",
            "  File \"/usr/local/lib/python3.10/dist-packages/sqlalchemy/engine/base.py\", line 2134, in _handle_dbapi_exception\n",
            "    util.raise_(\n",
            "  File \"/usr/local/lib/python3.10/dist-packages/sqlalchemy/util/compat.py\", line 211, in raise_\n",
            "    raise exception\n",
            "  File \"/usr/local/lib/python3.10/dist-packages/sqlalchemy/engine/base.py\", line 1062, in _rollback_impl\n",
            "    self.engine.dialect.do_rollback(self.connection)\n",
            "  File \"/usr/local/lib/python3.10/dist-packages/sqlalchemy/engine/default.py\", line 683, in do_rollback\n",
            "    dbapi_connection.rollback()\n",
            "sqlalchemy.exc.ProgrammingError: (sqlite3.ProgrammingError) SQLite objects created in a thread can only be used in that same thread. The object was created in thread id 139780940554240 and this is thread id 139780480284224.\n",
            "(Background on this error at: https://sqlalche.me/e/14/f405)\n",
            "Exception ignored in: <function SearchEngine.__del__ at 0x7f20f03b53f0>\n",
            "Traceback (most recent call last):\n",
            "  File \"/usr/local/lib/python3.10/dist-packages/uszipcode/search.py\", line 196, in __del__\n",
            "    self.close()\n",
            "  File \"/usr/local/lib/python3.10/dist-packages/uszipcode/search.py\", line 202, in close\n",
            "    self.ses.close()\n",
            "  File \"/usr/local/lib/python3.10/dist-packages/sqlalchemy/orm/session.py\", line 1816, in close\n",
            "    self._close_impl(invalidate=False)\n",
            "  File \"/usr/local/lib/python3.10/dist-packages/sqlalchemy/orm/session.py\", line 1858, in _close_impl\n",
            "    transaction.close(invalidate)\n",
            "  File \"/usr/local/lib/python3.10/dist-packages/sqlalchemy/orm/session.py\", line 926, in close\n",
            "    transaction.close()\n",
            "  File \"/usr/local/lib/python3.10/dist-packages/sqlalchemy/engine/base.py\", line 2426, in close\n",
            "    self._do_close()\n",
            "  File \"/usr/local/lib/python3.10/dist-packages/sqlalchemy/engine/base.py\", line 2649, in _do_close\n",
            "    self._close_impl()\n",
            "  File \"/usr/local/lib/python3.10/dist-packages/sqlalchemy/engine/base.py\", line 2635, in _close_impl\n",
            "    self._connection_rollback_impl()\n",
            "  File \"/usr/local/lib/python3.10/dist-packages/sqlalchemy/engine/base.py\", line 2627, in _connection_rollback_impl\n",
            "    self.connection._rollback_impl()\n",
            "  File \"/usr/local/lib/python3.10/dist-packages/sqlalchemy/engine/base.py\", line 1064, in _rollback_impl\n",
            "    self._handle_dbapi_exception(e, None, None, None, None)\n",
            "  File \"/usr/local/lib/python3.10/dist-packages/sqlalchemy/engine/base.py\", line 2134, in _handle_dbapi_exception\n",
            "    util.raise_(\n",
            "  File \"/usr/local/lib/python3.10/dist-packages/sqlalchemy/util/compat.py\", line 211, in raise_\n",
            "    raise exception\n",
            "  File \"/usr/local/lib/python3.10/dist-packages/sqlalchemy/engine/base.py\", line 1062, in _rollback_impl\n",
            "    self.engine.dialect.do_rollback(self.connection)\n",
            "  File \"/usr/local/lib/python3.10/dist-packages/sqlalchemy/engine/default.py\", line 683, in do_rollback\n",
            "    dbapi_connection.rollback()\n",
            "sqlalchemy.exc.ProgrammingError: (sqlite3.ProgrammingError) SQLite objects created in a thread can only be used in that same thread. The object was created in thread id 139780940554240 and this is thread id 139780480284224.\n",
            "(Background on this error at: https://sqlalche.me/e/14/f405)\n",
            "Exception ignored in: <function SearchEngine.__del__ at 0x7f20f03b53f0>\n",
            "Traceback (most recent call last):\n",
            "  File \"/usr/local/lib/python3.10/dist-packages/uszipcode/search.py\", line 196, in __del__\n",
            "    self.close()\n",
            "  File \"/usr/local/lib/python3.10/dist-packages/uszipcode/search.py\", line 202, in close\n",
            "    self.ses.close()\n",
            "  File \"/usr/local/lib/python3.10/dist-packages/sqlalchemy/orm/session.py\", line 1816, in close\n",
            "    self._close_impl(invalidate=False)\n",
            "  File \"/usr/local/lib/python3.10/dist-packages/sqlalchemy/orm/session.py\", line 1858, in _close_impl\n",
            "    transaction.close(invalidate)\n",
            "  File \"/usr/local/lib/python3.10/dist-packages/sqlalchemy/orm/session.py\", line 926, in close\n",
            "    transaction.close()\n",
            "  File \"/usr/local/lib/python3.10/dist-packages/sqlalchemy/engine/base.py\", line 2426, in close\n",
            "    self._do_close()\n",
            "  File \"/usr/local/lib/python3.10/dist-packages/sqlalchemy/engine/base.py\", line 2649, in _do_close\n",
            "    self._close_impl()\n",
            "  File \"/usr/local/lib/python3.10/dist-packages/sqlalchemy/engine/base.py\", line 2635, in _close_impl\n",
            "    self._connection_rollback_impl()\n",
            "  File \"/usr/local/lib/python3.10/dist-packages/sqlalchemy/engine/base.py\", line 2627, in _connection_rollback_impl\n",
            "    self.connection._rollback_impl()\n",
            "  File \"/usr/local/lib/python3.10/dist-packages/sqlalchemy/engine/base.py\", line 1064, in _rollback_impl\n",
            "    self._handle_dbapi_exception(e, None, None, None, None)\n",
            "  File \"/usr/local/lib/python3.10/dist-packages/sqlalchemy/engine/base.py\", line 2134, in _handle_dbapi_exception\n",
            "    util.raise_(\n",
            "  File \"/usr/local/lib/python3.10/dist-packages/sqlalchemy/util/compat.py\", line 211, in raise_\n",
            "    raise exception\n",
            "  File \"/usr/local/lib/python3.10/dist-packages/sqlalchemy/engine/base.py\", line 1062, in _rollback_impl\n",
            "    self.engine.dialect.do_rollback(self.connection)\n",
            "  File \"/usr/local/lib/python3.10/dist-packages/sqlalchemy/engine/default.py\", line 683, in do_rollback\n",
            "    dbapi_connection.rollback()\n",
            "sqlalchemy.exc.ProgrammingError: (sqlite3.ProgrammingError) SQLite objects created in a thread can only be used in that same thread. The object was created in thread id 139780940554240 and this is thread id 139780480284224.\n",
            "(Background on this error at: https://sqlalche.me/e/14/f405)\n",
            "Exception ignored in: <function SearchEngine.__del__ at 0x7f20f03b53f0>\n",
            "Traceback (most recent call last):\n",
            "  File \"/usr/local/lib/python3.10/dist-packages/uszipcode/search.py\", line 196, in __del__\n",
            "    self.close()\n",
            "  File \"/usr/local/lib/python3.10/dist-packages/uszipcode/search.py\", line 202, in close\n",
            "    self.ses.close()\n",
            "  File \"/usr/local/lib/python3.10/dist-packages/sqlalchemy/orm/session.py\", line 1816, in close\n",
            "    self._close_impl(invalidate=False)\n",
            "  File \"/usr/local/lib/python3.10/dist-packages/sqlalchemy/orm/session.py\", line 1858, in _close_impl\n",
            "    transaction.close(invalidate)\n",
            "  File \"/usr/local/lib/python3.10/dist-packages/sqlalchemy/orm/session.py\", line 926, in close\n",
            "    transaction.close()\n",
            "  File \"/usr/local/lib/python3.10/dist-packages/sqlalchemy/engine/base.py\", line 2426, in close\n",
            "    self._do_close()\n",
            "  File \"/usr/local/lib/python3.10/dist-packages/sqlalchemy/engine/base.py\", line 2649, in _do_close\n",
            "    self._close_impl()\n",
            "  File \"/usr/local/lib/python3.10/dist-packages/sqlalchemy/engine/base.py\", line 2635, in _close_impl\n",
            "    self._connection_rollback_impl()\n",
            "  File \"/usr/local/lib/python3.10/dist-packages/sqlalchemy/engine/base.py\", line 2627, in _connection_rollback_impl\n",
            "    self.connection._rollback_impl()\n",
            "  File \"/usr/local/lib/python3.10/dist-packages/sqlalchemy/engine/base.py\", line 1064, in _rollback_impl\n",
            "    self._handle_dbapi_exception(e, None, None, None, None)\n",
            "  File \"/usr/local/lib/python3.10/dist-packages/sqlalchemy/engine/base.py\", line 2134, in _handle_dbapi_exception\n",
            "    util.raise_(\n",
            "  File \"/usr/local/lib/python3.10/dist-packages/sqlalchemy/util/compat.py\", line 211, in raise_\n",
            "    raise exception\n",
            "  File \"/usr/local/lib/python3.10/dist-packages/sqlalchemy/engine/base.py\", line 1062, in _rollback_impl\n",
            "    self.engine.dialect.do_rollback(self.connection)\n",
            "  File \"/usr/local/lib/python3.10/dist-packages/sqlalchemy/engine/default.py\", line 683, in do_rollback\n",
            "    dbapi_connection.rollback()\n",
            "sqlalchemy.exc.ProgrammingError: (sqlite3.ProgrammingError) SQLite objects created in a thread can only be used in that same thread. The object was created in thread id 139780940554240 and this is thread id 139780480284224.\n",
            "(Background on this error at: https://sqlalche.me/e/14/f405)\n",
            "Exception ignored in: <function SearchEngine.__del__ at 0x7f20f03b53f0>\n",
            "Traceback (most recent call last):\n",
            "  File \"/usr/local/lib/python3.10/dist-packages/uszipcode/search.py\", line 196, in __del__\n",
            "    self.close()\n",
            "  File \"/usr/local/lib/python3.10/dist-packages/uszipcode/search.py\", line 202, in close\n",
            "    self.ses.close()\n",
            "  File \"/usr/local/lib/python3.10/dist-packages/sqlalchemy/orm/session.py\", line 1816, in close\n",
            "    self._close_impl(invalidate=False)\n",
            "  File \"/usr/local/lib/python3.10/dist-packages/sqlalchemy/orm/session.py\", line 1858, in _close_impl\n",
            "    transaction.close(invalidate)\n",
            "  File \"/usr/local/lib/python3.10/dist-packages/sqlalchemy/orm/session.py\", line 926, in close\n",
            "    transaction.close()\n",
            "  File \"/usr/local/lib/python3.10/dist-packages/sqlalchemy/engine/base.py\", line 2426, in close\n",
            "    self._do_close()\n",
            "  File \"/usr/local/lib/python3.10/dist-packages/sqlalchemy/engine/base.py\", line 2649, in _do_close\n",
            "    self._close_impl()\n",
            "  File \"/usr/local/lib/python3.10/dist-packages/sqlalchemy/engine/base.py\", line 2635, in _close_impl\n",
            "    self._connection_rollback_impl()\n",
            "  File \"/usr/local/lib/python3.10/dist-packages/sqlalchemy/engine/base.py\", line 2627, in _connection_rollback_impl\n",
            "    self.connection._rollback_impl()\n",
            "  File \"/usr/local/lib/python3.10/dist-packages/sqlalchemy/engine/base.py\", line 1064, in _rollback_impl\n",
            "    self._handle_dbapi_exception(e, None, None, None, None)\n",
            "  File \"/usr/local/lib/python3.10/dist-packages/sqlalchemy/engine/base.py\", line 2134, in _handle_dbapi_exception\n",
            "    util.raise_(\n",
            "  File \"/usr/local/lib/python3.10/dist-packages/sqlalchemy/util/compat.py\", line 211, in raise_\n",
            "    raise exception\n",
            "  File \"/usr/local/lib/python3.10/dist-packages/sqlalchemy/engine/base.py\", line 1062, in _rollback_impl\n",
            "    self.engine.dialect.do_rollback(self.connection)\n",
            "  File \"/usr/local/lib/python3.10/dist-packages/sqlalchemy/engine/default.py\", line 683, in do_rollback\n",
            "    dbapi_connection.rollback()\n",
            "sqlalchemy.exc.ProgrammingError: (sqlite3.ProgrammingError) SQLite objects created in a thread can only be used in that same thread. The object was created in thread id 139780940554240 and this is thread id 139780480284224.\n",
            "(Background on this error at: https://sqlalche.me/e/14/f405)\n",
            "Exception ignored in: <function SearchEngine.__del__ at 0x7f20f03b53f0>\n",
            "Traceback (most recent call last):\n",
            "  File \"/usr/local/lib/python3.10/dist-packages/uszipcode/search.py\", line 196, in __del__\n",
            "    self.close()\n",
            "  File \"/usr/local/lib/python3.10/dist-packages/uszipcode/search.py\", line 202, in close\n",
            "    self.ses.close()\n",
            "  File \"/usr/local/lib/python3.10/dist-packages/sqlalchemy/orm/session.py\", line 1816, in close\n",
            "    self._close_impl(invalidate=False)\n",
            "  File \"/usr/local/lib/python3.10/dist-packages/sqlalchemy/orm/session.py\", line 1858, in _close_impl\n",
            "    transaction.close(invalidate)\n",
            "  File \"/usr/local/lib/python3.10/dist-packages/sqlalchemy/orm/session.py\", line 926, in close\n",
            "    transaction.close()\n",
            "  File \"/usr/local/lib/python3.10/dist-packages/sqlalchemy/engine/base.py\", line 2426, in close\n",
            "    self._do_close()\n",
            "  File \"/usr/local/lib/python3.10/dist-packages/sqlalchemy/engine/base.py\", line 2649, in _do_close\n",
            "    self._close_impl()\n",
            "  File \"/usr/local/lib/python3.10/dist-packages/sqlalchemy/engine/base.py\", line 2635, in _close_impl\n",
            "    self._connection_rollback_impl()\n",
            "  File \"/usr/local/lib/python3.10/dist-packages/sqlalchemy/engine/base.py\", line 2627, in _connection_rollback_impl\n",
            "    self.connection._rollback_impl()\n",
            "  File \"/usr/local/lib/python3.10/dist-packages/sqlalchemy/engine/base.py\", line 1064, in _rollback_impl\n",
            "    self._handle_dbapi_exception(e, None, None, None, None)\n",
            "  File \"/usr/local/lib/python3.10/dist-packages/sqlalchemy/engine/base.py\", line 2134, in _handle_dbapi_exception\n",
            "    util.raise_(\n",
            "  File \"/usr/local/lib/python3.10/dist-packages/sqlalchemy/util/compat.py\", line 211, in raise_\n",
            "    raise exception\n",
            "  File \"/usr/local/lib/python3.10/dist-packages/sqlalchemy/engine/base.py\", line 1062, in _rollback_impl\n",
            "    self.engine.dialect.do_rollback(self.connection)\n",
            "  File \"/usr/local/lib/python3.10/dist-packages/sqlalchemy/engine/default.py\", line 683, in do_rollback\n",
            "    dbapi_connection.rollback()\n",
            "sqlalchemy.exc.ProgrammingError: (sqlite3.ProgrammingError) SQLite objects created in a thread can only be used in that same thread. The object was created in thread id 139780940554240 and this is thread id 139780480284224.\n",
            "(Background on this error at: https://sqlalche.me/e/14/f405)\n",
            "Exception ignored in: <function SearchEngine.__del__ at 0x7f20f03b53f0>\n",
            "Traceback (most recent call last):\n",
            "  File \"/usr/local/lib/python3.10/dist-packages/uszipcode/search.py\", line 196, in __del__\n",
            "    self.close()\n",
            "  File \"/usr/local/lib/python3.10/dist-packages/uszipcode/search.py\", line 202, in close\n",
            "    self.ses.close()\n",
            "  File \"/usr/local/lib/python3.10/dist-packages/sqlalchemy/orm/session.py\", line 1816, in close\n",
            "    self._close_impl(invalidate=False)\n",
            "  File \"/usr/local/lib/python3.10/dist-packages/sqlalchemy/orm/session.py\", line 1858, in _close_impl\n",
            "    transaction.close(invalidate)\n",
            "  File \"/usr/local/lib/python3.10/dist-packages/sqlalchemy/orm/session.py\", line 926, in close\n",
            "    transaction.close()\n",
            "  File \"/usr/local/lib/python3.10/dist-packages/sqlalchemy/engine/base.py\", line 2426, in close\n",
            "    self._do_close()\n",
            "  File \"/usr/local/lib/python3.10/dist-packages/sqlalchemy/engine/base.py\", line 2649, in _do_close\n",
            "    self._close_impl()\n",
            "  File \"/usr/local/lib/python3.10/dist-packages/sqlalchemy/engine/base.py\", line 2635, in _close_impl\n",
            "    self._connection_rollback_impl()\n",
            "  File \"/usr/local/lib/python3.10/dist-packages/sqlalchemy/engine/base.py\", line 2627, in _connection_rollback_impl\n",
            "    self.connection._rollback_impl()\n",
            "  File \"/usr/local/lib/python3.10/dist-packages/sqlalchemy/engine/base.py\", line 1064, in _rollback_impl\n",
            "    self._handle_dbapi_exception(e, None, None, None, None)\n",
            "  File \"/usr/local/lib/python3.10/dist-packages/sqlalchemy/engine/base.py\", line 2134, in _handle_dbapi_exception\n",
            "    util.raise_(\n",
            "  File \"/usr/local/lib/python3.10/dist-packages/sqlalchemy/util/compat.py\", line 211, in raise_\n",
            "    raise exception\n",
            "  File \"/usr/local/lib/python3.10/dist-packages/sqlalchemy/engine/base.py\", line 1062, in _rollback_impl\n",
            "    self.engine.dialect.do_rollback(self.connection)\n",
            "  File \"/usr/local/lib/python3.10/dist-packages/sqlalchemy/engine/default.py\", line 683, in do_rollback\n",
            "    dbapi_connection.rollback()\n",
            "sqlalchemy.exc.ProgrammingError: (sqlite3.ProgrammingError) SQLite objects created in a thread can only be used in that same thread. The object was created in thread id 139780940554240 and this is thread id 139780480284224.\n",
            "(Background on this error at: https://sqlalche.me/e/14/f405)\n",
            "Exception ignored in: <function SearchEngine.__del__ at 0x7f20f03b53f0>\n",
            "Traceback (most recent call last):\n",
            "  File \"/usr/local/lib/python3.10/dist-packages/uszipcode/search.py\", line 196, in __del__\n",
            "    self.close()\n",
            "  File \"/usr/local/lib/python3.10/dist-packages/uszipcode/search.py\", line 202, in close\n",
            "    self.ses.close()\n",
            "  File \"/usr/local/lib/python3.10/dist-packages/sqlalchemy/orm/session.py\", line 1816, in close\n",
            "    self._close_impl(invalidate=False)\n",
            "  File \"/usr/local/lib/python3.10/dist-packages/sqlalchemy/orm/session.py\", line 1858, in _close_impl\n",
            "    transaction.close(invalidate)\n",
            "  File \"/usr/local/lib/python3.10/dist-packages/sqlalchemy/orm/session.py\", line 926, in close\n",
            "    transaction.close()\n",
            "  File \"/usr/local/lib/python3.10/dist-packages/sqlalchemy/engine/base.py\", line 2426, in close\n",
            "    self._do_close()\n",
            "  File \"/usr/local/lib/python3.10/dist-packages/sqlalchemy/engine/base.py\", line 2649, in _do_close\n",
            "    self._close_impl()\n",
            "  File \"/usr/local/lib/python3.10/dist-packages/sqlalchemy/engine/base.py\", line 2635, in _close_impl\n",
            "    self._connection_rollback_impl()\n",
            "  File \"/usr/local/lib/python3.10/dist-packages/sqlalchemy/engine/base.py\", line 2627, in _connection_rollback_impl\n",
            "    self.connection._rollback_impl()\n",
            "  File \"/usr/local/lib/python3.10/dist-packages/sqlalchemy/engine/base.py\", line 1064, in _rollback_impl\n",
            "    self._handle_dbapi_exception(e, None, None, None, None)\n",
            "  File \"/usr/local/lib/python3.10/dist-packages/sqlalchemy/engine/base.py\", line 2134, in _handle_dbapi_exception\n",
            "    util.raise_(\n",
            "  File \"/usr/local/lib/python3.10/dist-packages/sqlalchemy/util/compat.py\", line 211, in raise_\n",
            "    raise exception\n",
            "  File \"/usr/local/lib/python3.10/dist-packages/sqlalchemy/engine/base.py\", line 1062, in _rollback_impl\n",
            "    self.engine.dialect.do_rollback(self.connection)\n",
            "  File \"/usr/local/lib/python3.10/dist-packages/sqlalchemy/engine/default.py\", line 683, in do_rollback\n",
            "    dbapi_connection.rollback()\n",
            "sqlalchemy.exc.ProgrammingError: (sqlite3.ProgrammingError) SQLite objects created in a thread can only be used in that same thread. The object was created in thread id 139780940554240 and this is thread id 139780480284224.\n",
            "(Background on this error at: https://sqlalche.me/e/14/f405)\n",
            "Exception ignored in: <function SearchEngine.__del__ at 0x7f20f03b53f0>\n",
            "Traceback (most recent call last):\n",
            "  File \"/usr/local/lib/python3.10/dist-packages/uszipcode/search.py\", line 196, in __del__\n",
            "    self.close()\n",
            "  File \"/usr/local/lib/python3.10/dist-packages/uszipcode/search.py\", line 202, in close\n",
            "    self.ses.close()\n",
            "  File \"/usr/local/lib/python3.10/dist-packages/sqlalchemy/orm/session.py\", line 1816, in close\n",
            "    self._close_impl(invalidate=False)\n",
            "  File \"/usr/local/lib/python3.10/dist-packages/sqlalchemy/orm/session.py\", line 1858, in _close_impl\n",
            "    transaction.close(invalidate)\n",
            "  File \"/usr/local/lib/python3.10/dist-packages/sqlalchemy/orm/session.py\", line 926, in close\n",
            "    transaction.close()\n",
            "  File \"/usr/local/lib/python3.10/dist-packages/sqlalchemy/engine/base.py\", line 2426, in close\n",
            "    self._do_close()\n",
            "  File \"/usr/local/lib/python3.10/dist-packages/sqlalchemy/engine/base.py\", line 2649, in _do_close\n",
            "    self._close_impl()\n",
            "  File \"/usr/local/lib/python3.10/dist-packages/sqlalchemy/engine/base.py\", line 2635, in _close_impl\n",
            "    self._connection_rollback_impl()\n",
            "  File \"/usr/local/lib/python3.10/dist-packages/sqlalchemy/engine/base.py\", line 2627, in _connection_rollback_impl\n",
            "    self.connection._rollback_impl()\n",
            "  File \"/usr/local/lib/python3.10/dist-packages/sqlalchemy/engine/base.py\", line 1064, in _rollback_impl\n",
            "    self._handle_dbapi_exception(e, None, None, None, None)\n",
            "  File \"/usr/local/lib/python3.10/dist-packages/sqlalchemy/engine/base.py\", line 2134, in _handle_dbapi_exception\n",
            "    util.raise_(\n",
            "  File \"/usr/local/lib/python3.10/dist-packages/sqlalchemy/util/compat.py\", line 211, in raise_\n",
            "    raise exception\n",
            "  File \"/usr/local/lib/python3.10/dist-packages/sqlalchemy/engine/base.py\", line 1062, in _rollback_impl\n",
            "    self.engine.dialect.do_rollback(self.connection)\n",
            "  File \"/usr/local/lib/python3.10/dist-packages/sqlalchemy/engine/default.py\", line 683, in do_rollback\n",
            "    dbapi_connection.rollback()\n",
            "sqlalchemy.exc.ProgrammingError: (sqlite3.ProgrammingError) SQLite objects created in a thread can only be used in that same thread. The object was created in thread id 139780940554240 and this is thread id 139780480284224.\n",
            "(Background on this error at: https://sqlalche.me/e/14/f405)\n",
            "Exception ignored in: <function SearchEngine.__del__ at 0x7f20f03b53f0>\n",
            "Traceback (most recent call last):\n",
            "  File \"/usr/local/lib/python3.10/dist-packages/uszipcode/search.py\", line 196, in __del__\n",
            "    self.close()\n",
            "  File \"/usr/local/lib/python3.10/dist-packages/uszipcode/search.py\", line 202, in close\n",
            "    self.ses.close()\n",
            "  File \"/usr/local/lib/python3.10/dist-packages/sqlalchemy/orm/session.py\", line 1816, in close\n",
            "    self._close_impl(invalidate=False)\n",
            "  File \"/usr/local/lib/python3.10/dist-packages/sqlalchemy/orm/session.py\", line 1858, in _close_impl\n",
            "    transaction.close(invalidate)\n",
            "  File \"/usr/local/lib/python3.10/dist-packages/sqlalchemy/orm/session.py\", line 926, in close\n",
            "    transaction.close()\n",
            "  File \"/usr/local/lib/python3.10/dist-packages/sqlalchemy/engine/base.py\", line 2426, in close\n",
            "    self._do_close()\n",
            "  File \"/usr/local/lib/python3.10/dist-packages/sqlalchemy/engine/base.py\", line 2649, in _do_close\n",
            "    self._close_impl()\n",
            "  File \"/usr/local/lib/python3.10/dist-packages/sqlalchemy/engine/base.py\", line 2635, in _close_impl\n",
            "    self._connection_rollback_impl()\n",
            "  File \"/usr/local/lib/python3.10/dist-packages/sqlalchemy/engine/base.py\", line 2627, in _connection_rollback_impl\n",
            "    self.connection._rollback_impl()\n",
            "  File \"/usr/local/lib/python3.10/dist-packages/sqlalchemy/engine/base.py\", line 1064, in _rollback_impl\n",
            "    self._handle_dbapi_exception(e, None, None, None, None)\n",
            "  File \"/usr/local/lib/python3.10/dist-packages/sqlalchemy/engine/base.py\", line 2134, in _handle_dbapi_exception\n",
            "    util.raise_(\n",
            "  File \"/usr/local/lib/python3.10/dist-packages/sqlalchemy/util/compat.py\", line 211, in raise_\n",
            "    raise exception\n",
            "  File \"/usr/local/lib/python3.10/dist-packages/sqlalchemy/engine/base.py\", line 1062, in _rollback_impl\n",
            "    self.engine.dialect.do_rollback(self.connection)\n",
            "  File \"/usr/local/lib/python3.10/dist-packages/sqlalchemy/engine/default.py\", line 683, in do_rollback\n",
            "    dbapi_connection.rollback()\n",
            "sqlalchemy.exc.ProgrammingError: (sqlite3.ProgrammingError) SQLite objects created in a thread can only be used in that same thread. The object was created in thread id 139780940554240 and this is thread id 139780480284224.\n",
            "(Background on this error at: https://sqlalche.me/e/14/f405)\n",
            "Exception ignored in: <function SearchEngine.__del__ at 0x7f20f03b53f0>\n",
            "Traceback (most recent call last):\n",
            "  File \"/usr/local/lib/python3.10/dist-packages/uszipcode/search.py\", line 196, in __del__\n",
            "    self.close()\n",
            "  File \"/usr/local/lib/python3.10/dist-packages/uszipcode/search.py\", line 202, in close\n",
            "    self.ses.close()\n",
            "  File \"/usr/local/lib/python3.10/dist-packages/sqlalchemy/orm/session.py\", line 1816, in close\n",
            "    self._close_impl(invalidate=False)\n",
            "  File \"/usr/local/lib/python3.10/dist-packages/sqlalchemy/orm/session.py\", line 1858, in _close_impl\n",
            "    transaction.close(invalidate)\n",
            "  File \"/usr/local/lib/python3.10/dist-packages/sqlalchemy/orm/session.py\", line 926, in close\n",
            "    transaction.close()\n",
            "  File \"/usr/local/lib/python3.10/dist-packages/sqlalchemy/engine/base.py\", line 2426, in close\n",
            "    self._do_close()\n",
            "  File \"/usr/local/lib/python3.10/dist-packages/sqlalchemy/engine/base.py\", line 2649, in _do_close\n",
            "    self._close_impl()\n",
            "  File \"/usr/local/lib/python3.10/dist-packages/sqlalchemy/engine/base.py\", line 2635, in _close_impl\n",
            "    self._connection_rollback_impl()\n",
            "  File \"/usr/local/lib/python3.10/dist-packages/sqlalchemy/engine/base.py\", line 2627, in _connection_rollback_impl\n",
            "    self.connection._rollback_impl()\n",
            "  File \"/usr/local/lib/python3.10/dist-packages/sqlalchemy/engine/base.py\", line 1064, in _rollback_impl\n",
            "    self._handle_dbapi_exception(e, None, None, None, None)\n",
            "  File \"/usr/local/lib/python3.10/dist-packages/sqlalchemy/engine/base.py\", line 2134, in _handle_dbapi_exception\n",
            "    util.raise_(\n",
            "  File \"/usr/local/lib/python3.10/dist-packages/sqlalchemy/util/compat.py\", line 211, in raise_\n",
            "    raise exception\n",
            "  File \"/usr/local/lib/python3.10/dist-packages/sqlalchemy/engine/base.py\", line 1062, in _rollback_impl\n",
            "    self.engine.dialect.do_rollback(self.connection)\n",
            "  File \"/usr/local/lib/python3.10/dist-packages/sqlalchemy/engine/default.py\", line 683, in do_rollback\n",
            "    dbapi_connection.rollback()\n",
            "sqlalchemy.exc.ProgrammingError: (sqlite3.ProgrammingError) SQLite objects created in a thread can only be used in that same thread. The object was created in thread id 139780940554240 and this is thread id 139780480284224.\n",
            "(Background on this error at: https://sqlalche.me/e/14/f405)\n",
            "Exception ignored in: <function SearchEngine.__del__ at 0x7f20f03b53f0>\n",
            "Traceback (most recent call last):\n",
            "  File \"/usr/local/lib/python3.10/dist-packages/uszipcode/search.py\", line 196, in __del__\n",
            "    self.close()\n",
            "  File \"/usr/local/lib/python3.10/dist-packages/uszipcode/search.py\", line 202, in close\n",
            "    self.ses.close()\n",
            "  File \"/usr/local/lib/python3.10/dist-packages/sqlalchemy/orm/session.py\", line 1816, in close\n",
            "    self._close_impl(invalidate=False)\n",
            "  File \"/usr/local/lib/python3.10/dist-packages/sqlalchemy/orm/session.py\", line 1858, in _close_impl\n",
            "    transaction.close(invalidate)\n",
            "  File \"/usr/local/lib/python3.10/dist-packages/sqlalchemy/orm/session.py\", line 926, in close\n",
            "    transaction.close()\n",
            "  File \"/usr/local/lib/python3.10/dist-packages/sqlalchemy/engine/base.py\", line 2426, in close\n",
            "    self._do_close()\n",
            "  File \"/usr/local/lib/python3.10/dist-packages/sqlalchemy/engine/base.py\", line 2649, in _do_close\n",
            "    self._close_impl()\n",
            "  File \"/usr/local/lib/python3.10/dist-packages/sqlalchemy/engine/base.py\", line 2635, in _close_impl\n",
            "    self._connection_rollback_impl()\n",
            "  File \"/usr/local/lib/python3.10/dist-packages/sqlalchemy/engine/base.py\", line 2627, in _connection_rollback_impl\n",
            "    self.connection._rollback_impl()\n",
            "  File \"/usr/local/lib/python3.10/dist-packages/sqlalchemy/engine/base.py\", line 1064, in _rollback_impl\n",
            "    self._handle_dbapi_exception(e, None, None, None, None)\n",
            "  File \"/usr/local/lib/python3.10/dist-packages/sqlalchemy/engine/base.py\", line 2134, in _handle_dbapi_exception\n",
            "    util.raise_(\n",
            "  File \"/usr/local/lib/python3.10/dist-packages/sqlalchemy/util/compat.py\", line 211, in raise_\n",
            "    raise exception\n",
            "  File \"/usr/local/lib/python3.10/dist-packages/sqlalchemy/engine/base.py\", line 1062, in _rollback_impl\n",
            "    self.engine.dialect.do_rollback(self.connection)\n",
            "  File \"/usr/local/lib/python3.10/dist-packages/sqlalchemy/engine/default.py\", line 683, in do_rollback\n",
            "    dbapi_connection.rollback()\n",
            "sqlalchemy.exc.ProgrammingError: (sqlite3.ProgrammingError) SQLite objects created in a thread can only be used in that same thread. The object was created in thread id 139780940554240 and this is thread id 139780480284224.\n",
            "(Background on this error at: https://sqlalche.me/e/14/f405)\n",
            "Exception ignored in: <function SearchEngine.__del__ at 0x7f20f03b53f0>\n",
            "Traceback (most recent call last):\n",
            "  File \"/usr/local/lib/python3.10/dist-packages/uszipcode/search.py\", line 196, in __del__\n",
            "    self.close()\n",
            "  File \"/usr/local/lib/python3.10/dist-packages/uszipcode/search.py\", line 202, in close\n",
            "    self.ses.close()\n",
            "  File \"/usr/local/lib/python3.10/dist-packages/sqlalchemy/orm/session.py\", line 1816, in close\n",
            "    self._close_impl(invalidate=False)\n",
            "  File \"/usr/local/lib/python3.10/dist-packages/sqlalchemy/orm/session.py\", line 1858, in _close_impl\n",
            "    transaction.close(invalidate)\n",
            "  File \"/usr/local/lib/python3.10/dist-packages/sqlalchemy/orm/session.py\", line 926, in close\n",
            "    transaction.close()\n",
            "  File \"/usr/local/lib/python3.10/dist-packages/sqlalchemy/engine/base.py\", line 2426, in close\n",
            "    self._do_close()\n",
            "  File \"/usr/local/lib/python3.10/dist-packages/sqlalchemy/engine/base.py\", line 2649, in _do_close\n",
            "    self._close_impl()\n",
            "  File \"/usr/local/lib/python3.10/dist-packages/sqlalchemy/engine/base.py\", line 2635, in _close_impl\n",
            "    self._connection_rollback_impl()\n",
            "  File \"/usr/local/lib/python3.10/dist-packages/sqlalchemy/engine/base.py\", line 2627, in _connection_rollback_impl\n",
            "    self.connection._rollback_impl()\n",
            "  File \"/usr/local/lib/python3.10/dist-packages/sqlalchemy/engine/base.py\", line 1064, in _rollback_impl\n",
            "    self._handle_dbapi_exception(e, None, None, None, None)\n",
            "  File \"/usr/local/lib/python3.10/dist-packages/sqlalchemy/engine/base.py\", line 2134, in _handle_dbapi_exception\n",
            "    util.raise_(\n",
            "  File \"/usr/local/lib/python3.10/dist-packages/sqlalchemy/util/compat.py\", line 211, in raise_\n",
            "    raise exception\n",
            "  File \"/usr/local/lib/python3.10/dist-packages/sqlalchemy/engine/base.py\", line 1062, in _rollback_impl\n",
            "    self.engine.dialect.do_rollback(self.connection)\n",
            "  File \"/usr/local/lib/python3.10/dist-packages/sqlalchemy/engine/default.py\", line 683, in do_rollback\n",
            "    dbapi_connection.rollback()\n",
            "sqlalchemy.exc.ProgrammingError: (sqlite3.ProgrammingError) SQLite objects created in a thread can only be used in that same thread. The object was created in thread id 139780940554240 and this is thread id 139780480284224.\n",
            "(Background on this error at: https://sqlalche.me/e/14/f405)\n",
            "Exception ignored in: <function SearchEngine.__del__ at 0x7f20f03b53f0>\n",
            "Traceback (most recent call last):\n",
            "  File \"/usr/local/lib/python3.10/dist-packages/uszipcode/search.py\", line 196, in __del__\n",
            "    self.close()\n",
            "  File \"/usr/local/lib/python3.10/dist-packages/uszipcode/search.py\", line 202, in close\n",
            "    self.ses.close()\n",
            "  File \"/usr/local/lib/python3.10/dist-packages/sqlalchemy/orm/session.py\", line 1816, in close\n",
            "    self._close_impl(invalidate=False)\n",
            "  File \"/usr/local/lib/python3.10/dist-packages/sqlalchemy/orm/session.py\", line 1858, in _close_impl\n",
            "    transaction.close(invalidate)\n",
            "  File \"/usr/local/lib/python3.10/dist-packages/sqlalchemy/orm/session.py\", line 926, in close\n",
            "    transaction.close()\n",
            "  File \"/usr/local/lib/python3.10/dist-packages/sqlalchemy/engine/base.py\", line 2426, in close\n",
            "    self._do_close()\n",
            "  File \"/usr/local/lib/python3.10/dist-packages/sqlalchemy/engine/base.py\", line 2649, in _do_close\n",
            "    self._close_impl()\n",
            "  File \"/usr/local/lib/python3.10/dist-packages/sqlalchemy/engine/base.py\", line 2635, in _close_impl\n",
            "    self._connection_rollback_impl()\n",
            "  File \"/usr/local/lib/python3.10/dist-packages/sqlalchemy/engine/base.py\", line 2627, in _connection_rollback_impl\n",
            "    self.connection._rollback_impl()\n",
            "  File \"/usr/local/lib/python3.10/dist-packages/sqlalchemy/engine/base.py\", line 1064, in _rollback_impl\n",
            "    self._handle_dbapi_exception(e, None, None, None, None)\n",
            "  File \"/usr/local/lib/python3.10/dist-packages/sqlalchemy/engine/base.py\", line 2134, in _handle_dbapi_exception\n",
            "    util.raise_(\n",
            "  File \"/usr/local/lib/python3.10/dist-packages/sqlalchemy/util/compat.py\", line 211, in raise_\n",
            "    raise exception\n",
            "  File \"/usr/local/lib/python3.10/dist-packages/sqlalchemy/engine/base.py\", line 1062, in _rollback_impl\n",
            "    self.engine.dialect.do_rollback(self.connection)\n",
            "  File \"/usr/local/lib/python3.10/dist-packages/sqlalchemy/engine/default.py\", line 683, in do_rollback\n",
            "    dbapi_connection.rollback()\n",
            "sqlalchemy.exc.ProgrammingError: (sqlite3.ProgrammingError) SQLite objects created in a thread can only be used in that same thread. The object was created in thread id 139780940554240 and this is thread id 139780480284224.\n",
            "(Background on this error at: https://sqlalche.me/e/14/f405)\n",
            "Exception ignored in: <function SearchEngine.__del__ at 0x7f20f03b53f0>\n",
            "Traceback (most recent call last):\n",
            "  File \"/usr/local/lib/python3.10/dist-packages/uszipcode/search.py\", line 196, in __del__\n",
            "    self.close()\n",
            "  File \"/usr/local/lib/python3.10/dist-packages/uszipcode/search.py\", line 202, in close\n",
            "    self.ses.close()\n",
            "  File \"/usr/local/lib/python3.10/dist-packages/sqlalchemy/orm/session.py\", line 1816, in close\n",
            "    self._close_impl(invalidate=False)\n",
            "  File \"/usr/local/lib/python3.10/dist-packages/sqlalchemy/orm/session.py\", line 1858, in _close_impl\n",
            "    transaction.close(invalidate)\n",
            "  File \"/usr/local/lib/python3.10/dist-packages/sqlalchemy/orm/session.py\", line 926, in close\n",
            "    transaction.close()\n",
            "  File \"/usr/local/lib/python3.10/dist-packages/sqlalchemy/engine/base.py\", line 2426, in close\n",
            "    self._do_close()\n",
            "  File \"/usr/local/lib/python3.10/dist-packages/sqlalchemy/engine/base.py\", line 2649, in _do_close\n",
            "    self._close_impl()\n",
            "  File \"/usr/local/lib/python3.10/dist-packages/sqlalchemy/engine/base.py\", line 2635, in _close_impl\n",
            "    self._connection_rollback_impl()\n",
            "  File \"/usr/local/lib/python3.10/dist-packages/sqlalchemy/engine/base.py\", line 2627, in _connection_rollback_impl\n",
            "    self.connection._rollback_impl()\n",
            "  File \"/usr/local/lib/python3.10/dist-packages/sqlalchemy/engine/base.py\", line 1064, in _rollback_impl\n",
            "    self._handle_dbapi_exception(e, None, None, None, None)\n",
            "  File \"/usr/local/lib/python3.10/dist-packages/sqlalchemy/engine/base.py\", line 2134, in _handle_dbapi_exception\n",
            "    util.raise_(\n",
            "  File \"/usr/local/lib/python3.10/dist-packages/sqlalchemy/util/compat.py\", line 211, in raise_\n",
            "    raise exception\n",
            "  File \"/usr/local/lib/python3.10/dist-packages/sqlalchemy/engine/base.py\", line 1062, in _rollback_impl\n",
            "    self.engine.dialect.do_rollback(self.connection)\n",
            "  File \"/usr/local/lib/python3.10/dist-packages/sqlalchemy/engine/default.py\", line 683, in do_rollback\n",
            "    dbapi_connection.rollback()\n",
            "sqlalchemy.exc.ProgrammingError: (sqlite3.ProgrammingError) SQLite objects created in a thread can only be used in that same thread. The object was created in thread id 139780940554240 and this is thread id 139780480284224.\n",
            "(Background on this error at: https://sqlalche.me/e/14/f405)\n",
            "Exception ignored in: <function SearchEngine.__del__ at 0x7f20f03b53f0>\n",
            "Traceback (most recent call last):\n",
            "  File \"/usr/local/lib/python3.10/dist-packages/uszipcode/search.py\", line 196, in __del__\n",
            "    self.close()\n",
            "  File \"/usr/local/lib/python3.10/dist-packages/uszipcode/search.py\", line 202, in close\n",
            "    self.ses.close()\n",
            "  File \"/usr/local/lib/python3.10/dist-packages/sqlalchemy/orm/session.py\", line 1816, in close\n",
            "    self._close_impl(invalidate=False)\n",
            "  File \"/usr/local/lib/python3.10/dist-packages/sqlalchemy/orm/session.py\", line 1858, in _close_impl\n",
            "    transaction.close(invalidate)\n",
            "  File \"/usr/local/lib/python3.10/dist-packages/sqlalchemy/orm/session.py\", line 926, in close\n",
            "    transaction.close()\n",
            "  File \"/usr/local/lib/python3.10/dist-packages/sqlalchemy/engine/base.py\", line 2426, in close\n",
            "    self._do_close()\n",
            "  File \"/usr/local/lib/python3.10/dist-packages/sqlalchemy/engine/base.py\", line 2649, in _do_close\n",
            "    self._close_impl()\n",
            "  File \"/usr/local/lib/python3.10/dist-packages/sqlalchemy/engine/base.py\", line 2635, in _close_impl\n",
            "    self._connection_rollback_impl()\n",
            "  File \"/usr/local/lib/python3.10/dist-packages/sqlalchemy/engine/base.py\", line 2627, in _connection_rollback_impl\n",
            "    self.connection._rollback_impl()\n",
            "  File \"/usr/local/lib/python3.10/dist-packages/sqlalchemy/engine/base.py\", line 1064, in _rollback_impl\n",
            "    self._handle_dbapi_exception(e, None, None, None, None)\n",
            "  File \"/usr/local/lib/python3.10/dist-packages/sqlalchemy/engine/base.py\", line 2134, in _handle_dbapi_exception\n",
            "    util.raise_(\n",
            "  File \"/usr/local/lib/python3.10/dist-packages/sqlalchemy/util/compat.py\", line 211, in raise_\n",
            "    raise exception\n",
            "  File \"/usr/local/lib/python3.10/dist-packages/sqlalchemy/engine/base.py\", line 1062, in _rollback_impl\n",
            "    self.engine.dialect.do_rollback(self.connection)\n",
            "  File \"/usr/local/lib/python3.10/dist-packages/sqlalchemy/engine/default.py\", line 683, in do_rollback\n",
            "    dbapi_connection.rollback()\n",
            "sqlalchemy.exc.ProgrammingError: (sqlite3.ProgrammingError) SQLite objects created in a thread can only be used in that same thread. The object was created in thread id 139780940554240 and this is thread id 139780480284224.\n",
            "(Background on this error at: https://sqlalche.me/e/14/f405)\n",
            "Exception ignored in: <function SearchEngine.__del__ at 0x7f20f03b53f0>\n",
            "Traceback (most recent call last):\n",
            "  File \"/usr/local/lib/python3.10/dist-packages/uszipcode/search.py\", line 196, in __del__\n",
            "    self.close()\n",
            "  File \"/usr/local/lib/python3.10/dist-packages/uszipcode/search.py\", line 202, in close\n",
            "    self.ses.close()\n",
            "  File \"/usr/local/lib/python3.10/dist-packages/sqlalchemy/orm/session.py\", line 1816, in close\n",
            "    self._close_impl(invalidate=False)\n",
            "  File \"/usr/local/lib/python3.10/dist-packages/sqlalchemy/orm/session.py\", line 1858, in _close_impl\n",
            "    transaction.close(invalidate)\n",
            "  File \"/usr/local/lib/python3.10/dist-packages/sqlalchemy/orm/session.py\", line 926, in close\n",
            "    transaction.close()\n",
            "  File \"/usr/local/lib/python3.10/dist-packages/sqlalchemy/engine/base.py\", line 2426, in close\n",
            "    self._do_close()\n",
            "  File \"/usr/local/lib/python3.10/dist-packages/sqlalchemy/engine/base.py\", line 2649, in _do_close\n",
            "    self._close_impl()\n",
            "  File \"/usr/local/lib/python3.10/dist-packages/sqlalchemy/engine/base.py\", line 2635, in _close_impl\n",
            "    self._connection_rollback_impl()\n",
            "  File \"/usr/local/lib/python3.10/dist-packages/sqlalchemy/engine/base.py\", line 2627, in _connection_rollback_impl\n",
            "    self.connection._rollback_impl()\n",
            "  File \"/usr/local/lib/python3.10/dist-packages/sqlalchemy/engine/base.py\", line 1064, in _rollback_impl\n",
            "    self._handle_dbapi_exception(e, None, None, None, None)\n",
            "  File \"/usr/local/lib/python3.10/dist-packages/sqlalchemy/engine/base.py\", line 2134, in _handle_dbapi_exception\n",
            "    util.raise_(\n",
            "  File \"/usr/local/lib/python3.10/dist-packages/sqlalchemy/util/compat.py\", line 211, in raise_\n",
            "    raise exception\n",
            "  File \"/usr/local/lib/python3.10/dist-packages/sqlalchemy/engine/base.py\", line 1062, in _rollback_impl\n",
            "    self.engine.dialect.do_rollback(self.connection)\n",
            "  File \"/usr/local/lib/python3.10/dist-packages/sqlalchemy/engine/default.py\", line 683, in do_rollback\n",
            "    dbapi_connection.rollback()\n",
            "sqlalchemy.exc.ProgrammingError: (sqlite3.ProgrammingError) SQLite objects created in a thread can only be used in that same thread. The object was created in thread id 139780940554240 and this is thread id 139780480284224.\n",
            "(Background on this error at: https://sqlalche.me/e/14/f405)\n",
            "Exception ignored in: <function SearchEngine.__del__ at 0x7f20f03b53f0>\n",
            "Traceback (most recent call last):\n",
            "  File \"/usr/local/lib/python3.10/dist-packages/uszipcode/search.py\", line 196, in __del__\n",
            "    self.close()\n",
            "  File \"/usr/local/lib/python3.10/dist-packages/uszipcode/search.py\", line 202, in close\n",
            "    self.ses.close()\n",
            "  File \"/usr/local/lib/python3.10/dist-packages/sqlalchemy/orm/session.py\", line 1816, in close\n",
            "    self._close_impl(invalidate=False)\n",
            "  File \"/usr/local/lib/python3.10/dist-packages/sqlalchemy/orm/session.py\", line 1858, in _close_impl\n",
            "    transaction.close(invalidate)\n",
            "  File \"/usr/local/lib/python3.10/dist-packages/sqlalchemy/orm/session.py\", line 926, in close\n",
            "    transaction.close()\n",
            "  File \"/usr/local/lib/python3.10/dist-packages/sqlalchemy/engine/base.py\", line 2426, in close\n",
            "    self._do_close()\n",
            "  File \"/usr/local/lib/python3.10/dist-packages/sqlalchemy/engine/base.py\", line 2649, in _do_close\n",
            "    self._close_impl()\n",
            "  File \"/usr/local/lib/python3.10/dist-packages/sqlalchemy/engine/base.py\", line 2635, in _close_impl\n",
            "    self._connection_rollback_impl()\n",
            "  File \"/usr/local/lib/python3.10/dist-packages/sqlalchemy/engine/base.py\", line 2627, in _connection_rollback_impl\n",
            "    self.connection._rollback_impl()\n",
            "  File \"/usr/local/lib/python3.10/dist-packages/sqlalchemy/engine/base.py\", line 1064, in _rollback_impl\n",
            "    self._handle_dbapi_exception(e, None, None, None, None)\n",
            "  File \"/usr/local/lib/python3.10/dist-packages/sqlalchemy/engine/base.py\", line 2134, in _handle_dbapi_exception\n",
            "    util.raise_(\n",
            "  File \"/usr/local/lib/python3.10/dist-packages/sqlalchemy/util/compat.py\", line 211, in raise_\n",
            "    raise exception\n",
            "  File \"/usr/local/lib/python3.10/dist-packages/sqlalchemy/engine/base.py\", line 1062, in _rollback_impl\n",
            "    self.engine.dialect.do_rollback(self.connection)\n",
            "  File \"/usr/local/lib/python3.10/dist-packages/sqlalchemy/engine/default.py\", line 683, in do_rollback\n",
            "    dbapi_connection.rollback()\n",
            "sqlalchemy.exc.ProgrammingError: (sqlite3.ProgrammingError) SQLite objects created in a thread can only be used in that same thread. The object was created in thread id 139780940554240 and this is thread id 139780480284224.\n",
            "(Background on this error at: https://sqlalche.me/e/14/f405)\n",
            "Exception ignored in: <function SearchEngine.__del__ at 0x7f20f03b53f0>\n",
            "Traceback (most recent call last):\n",
            "  File \"/usr/local/lib/python3.10/dist-packages/uszipcode/search.py\", line 196, in __del__\n",
            "    self.close()\n",
            "  File \"/usr/local/lib/python3.10/dist-packages/uszipcode/search.py\", line 202, in close\n",
            "    self.ses.close()\n",
            "  File \"/usr/local/lib/python3.10/dist-packages/sqlalchemy/orm/session.py\", line 1816, in close\n",
            "    self._close_impl(invalidate=False)\n",
            "  File \"/usr/local/lib/python3.10/dist-packages/sqlalchemy/orm/session.py\", line 1858, in _close_impl\n",
            "    transaction.close(invalidate)\n",
            "  File \"/usr/local/lib/python3.10/dist-packages/sqlalchemy/orm/session.py\", line 926, in close\n",
            "    transaction.close()\n",
            "  File \"/usr/local/lib/python3.10/dist-packages/sqlalchemy/engine/base.py\", line 2426, in close\n",
            "    self._do_close()\n",
            "  File \"/usr/local/lib/python3.10/dist-packages/sqlalchemy/engine/base.py\", line 2649, in _do_close\n",
            "    self._close_impl()\n",
            "  File \"/usr/local/lib/python3.10/dist-packages/sqlalchemy/engine/base.py\", line 2635, in _close_impl\n",
            "    self._connection_rollback_impl()\n",
            "  File \"/usr/local/lib/python3.10/dist-packages/sqlalchemy/engine/base.py\", line 2627, in _connection_rollback_impl\n",
            "    self.connection._rollback_impl()\n",
            "  File \"/usr/local/lib/python3.10/dist-packages/sqlalchemy/engine/base.py\", line 1064, in _rollback_impl\n",
            "    self._handle_dbapi_exception(e, None, None, None, None)\n",
            "  File \"/usr/local/lib/python3.10/dist-packages/sqlalchemy/engine/base.py\", line 2134, in _handle_dbapi_exception\n",
            "    util.raise_(\n",
            "  File \"/usr/local/lib/python3.10/dist-packages/sqlalchemy/util/compat.py\", line 211, in raise_\n",
            "    raise exception\n",
            "  File \"/usr/local/lib/python3.10/dist-packages/sqlalchemy/engine/base.py\", line 1062, in _rollback_impl\n",
            "    self.engine.dialect.do_rollback(self.connection)\n",
            "  File \"/usr/local/lib/python3.10/dist-packages/sqlalchemy/engine/default.py\", line 683, in do_rollback\n",
            "    dbapi_connection.rollback()\n",
            "sqlalchemy.exc.ProgrammingError: (sqlite3.ProgrammingError) SQLite objects created in a thread can only be used in that same thread. The object was created in thread id 139780940554240 and this is thread id 139780480284224.\n",
            "(Background on this error at: https://sqlalche.me/e/14/f405)\n",
            "Exception ignored in: <function SearchEngine.__del__ at 0x7f20f03b53f0>\n",
            "Traceback (most recent call last):\n",
            "  File \"/usr/local/lib/python3.10/dist-packages/uszipcode/search.py\", line 196, in __del__\n",
            "    self.close()\n",
            "  File \"/usr/local/lib/python3.10/dist-packages/uszipcode/search.py\", line 202, in close\n",
            "    self.ses.close()\n",
            "  File \"/usr/local/lib/python3.10/dist-packages/sqlalchemy/orm/session.py\", line 1816, in close\n",
            "    self._close_impl(invalidate=False)\n",
            "  File \"/usr/local/lib/python3.10/dist-packages/sqlalchemy/orm/session.py\", line 1858, in _close_impl\n",
            "    transaction.close(invalidate)\n",
            "  File \"/usr/local/lib/python3.10/dist-packages/sqlalchemy/orm/session.py\", line 926, in close\n",
            "    transaction.close()\n",
            "  File \"/usr/local/lib/python3.10/dist-packages/sqlalchemy/engine/base.py\", line 2426, in close\n",
            "    self._do_close()\n",
            "  File \"/usr/local/lib/python3.10/dist-packages/sqlalchemy/engine/base.py\", line 2649, in _do_close\n",
            "    self._close_impl()\n",
            "  File \"/usr/local/lib/python3.10/dist-packages/sqlalchemy/engine/base.py\", line 2635, in _close_impl\n",
            "    self._connection_rollback_impl()\n",
            "  File \"/usr/local/lib/python3.10/dist-packages/sqlalchemy/engine/base.py\", line 2627, in _connection_rollback_impl\n",
            "    self.connection._rollback_impl()\n",
            "  File \"/usr/local/lib/python3.10/dist-packages/sqlalchemy/engine/base.py\", line 1064, in _rollback_impl\n",
            "    self._handle_dbapi_exception(e, None, None, None, None)\n",
            "  File \"/usr/local/lib/python3.10/dist-packages/sqlalchemy/engine/base.py\", line 2134, in _handle_dbapi_exception\n",
            "    util.raise_(\n",
            "  File \"/usr/local/lib/python3.10/dist-packages/sqlalchemy/util/compat.py\", line 211, in raise_\n",
            "    raise exception\n",
            "  File \"/usr/local/lib/python3.10/dist-packages/sqlalchemy/engine/base.py\", line 1062, in _rollback_impl\n",
            "    self.engine.dialect.do_rollback(self.connection)\n",
            "  File \"/usr/local/lib/python3.10/dist-packages/sqlalchemy/engine/default.py\", line 683, in do_rollback\n",
            "    dbapi_connection.rollback()\n",
            "sqlalchemy.exc.ProgrammingError: (sqlite3.ProgrammingError) SQLite objects created in a thread can only be used in that same thread. The object was created in thread id 139780940554240 and this is thread id 139780480284224.\n",
            "(Background on this error at: https://sqlalche.me/e/14/f405)\n"
          ]
        },
        {
          "output_type": "execute_result",
          "data": {
            "text/plain": [
              "ZipCodes\n",
              "37208    232\n",
              "37203    190\n",
              "37212    184\n",
              "37206    166\n",
              "37211    147\n",
              "37210    136\n",
              "37245    135\n",
              "37228    134\n",
              "37207    132\n",
              "37213    117\n",
              "37216    111\n",
              "37115     98\n",
              "37204     97\n",
              "37201     88\n",
              "37217     86\n",
              "37013     74\n",
              "37214     74\n",
              "37138     67\n",
              "37218     66\n",
              "37205     63\n",
              "37221     33\n",
              "37072     22\n",
              "37130     16\n",
              "37086     12\n",
              "37076     11\n",
              "37167     11\n",
              "37220      9\n",
              "37215      8\n",
              "37189      5\n",
              "Name: count, dtype: int64"
            ]
          },
          "metadata": {},
          "execution_count": 6
        }
      ]
    },
    {
      "cell_type": "code",
      "source": [
        "numStops = [232,190,136,134,132]\n",
        "zips = [37208,37203,37210,37228,37207]\n",
        "dfnew = pd.DataFrame(data={'zip': zips, 'numStops': numStops})"
      ],
      "metadata": {
        "id": "nHNbPQ-c1zUC"
      },
      "execution_count": null,
      "outputs": []
    },
    {
      "cell_type": "code",
      "source": [
        "sns.barplot(data=dfnew, x='zip', y='numStops',palette='rocket')\n",
        "plt.title(\"Stops by Low Income Zip Codes\")"
      ],
      "metadata": {
        "colab": {
          "base_uri": "https://localhost:8080/",
          "height": 599
        },
        "id": "ZQOrpmce1hDy",
        "outputId": "fb1c6c76-5d67-4552-cb71-2ce03eef2915"
      },
      "execution_count": null,
      "outputs": [
        {
          "output_type": "stream",
          "name": "stderr",
          "text": [
            "<ipython-input-25-83f67a6149fa>:1: FutureWarning: \n",
            "\n",
            "Passing `palette` without assigning `hue` is deprecated and will be removed in v0.14.0. Assign the `x` variable to `hue` and set `legend=False` for the same effect.\n",
            "\n",
            "  sns.barplot(data=dfnew, x='zip', y='numStops',palette='rocket')\n"
          ]
        },
        {
          "output_type": "execute_result",
          "data": {
            "text/plain": [
              "Text(0.5, 1.0, 'Stops by Low Income Zip Codes')"
            ]
          },
          "metadata": {},
          "execution_count": 25
        },
        {
          "output_type": "display_data",
          "data": {
            "text/plain": [
              "<Figure size 640x480 with 1 Axes>"
            ],
            "image/png": "iVBORw0KGgoAAAANSUhEUgAAAjsAAAHHCAYAAABZbpmkAAAAOXRFWHRTb2Z0d2FyZQBNYXRwbG90bGliIHZlcnNpb24zLjcuMSwgaHR0cHM6Ly9tYXRwbG90bGliLm9yZy/bCgiHAAAACXBIWXMAAA9hAAAPYQGoP6dpAAA4l0lEQVR4nO3deXgUVf7+/buzh4QkhJAEMOwgyCIMMhAkoBIIiyCLgyDKqsxXNpVRFscRERRhUFQGREdlUxZxQUXZjAgqQWUTUIygIIyQoCgkgCSQnN8fPumHNgFCp6E7h/fruuq66FOnqj7VJ53c1NYOY4wRAACApfy8XQAAAMClRNgBAABWI+wAAACrEXYAAIDVCDsAAMBqhB0AAGA1wg4AALAaYQcAAFiNsAMAAKxG2AFKgWrVqunmm2/2dhkoRebOnSuHw6F9+/Z5uxS3PProo3I4HN4uA5Yg7MBaO3bs0K233qqqVasqJCRElStXVrt27TRjxgyXfk888YSWLVvmnSJ9yL59++RwODRt2jRvl+LCV+u63ArCy4WmSx1uTp06penTp6t58+aKjIxUSEiI6tSpo+HDh+u77767pNsG3BXg7QKAS2HDhg268cYbVaVKFd19992Kj4/XgQMHtHHjRj377LMaMWKEs+8TTzyhW2+9Vd26dfNewcAFtG7dWgsWLChy3k8//aRx48apWrVqio2NlSTdeeed6t27t4KDgz1Wwy+//KIOHTpo8+bNuvnmm3X77bcrPDxc6enpWrx4sV588UXl5uZ6bHuApxB2YKXHH39ckZGR+vLLLxUVFeUy7/Dhw94pCiiBGjVqqEaNGoXa8/LydNNNNykgIECLFi1SmTJlJEn+/v7y9/f3aA0DBgzQ1q1b9cYbb6hnz54u8yZOnKh//vOfHt0e4CmcxoKVvv/+e9WvX79Q0JHk/J+vJDkcDp04cULz5s1zngYYMGCAc/7WrVvVsWNHRUREKDw8XG3bttXGjRtd1ldwemH9+vX6+9//rvLlyysiIkL9+vXTb7/95tJ306ZNSklJUUxMjEJDQ1W9enUNGjSo2Pu1evVqNW7cWCEhIbrmmmv01ltvOef98MMPcjgcmj59eqHlNmzYIIfDoUWLFhV7W+dy+PBhDR48WHFxcQoJCdG1116refPmufT5y1/+oh49eri0NWzYUA6HQ9u3b3e2LVmyRA6HQ7t27bqoGgre888++0yjRo1ShQoVFBYWpu7du+vnn38u1H/FihVq06aNypYtq4iICDVr1kwLFy506bN06VI1bdpUoaGhiomJ0R133KGffvrJpc+AAQMUHh6u/fv36+abb1Z4eLgqV66smTNnSvrj1OlNN92ksLAwVa1atdA2JOno0aO67777lJCQoODgYNWqVUtTpkxRfn7+Rb0HBSZMmKD169dr0qRJat68eaH36OzTWgXXfp3v5+hcPv/8c73//vsaPHhwoaAjScHBwYVONX700UdKSkpSWFiYoqKidMsttxQ51p9++qmaNWumkJAQ1axZUy+88MI563j11Ved4xQdHa3evXvrwIEDLn12796tnj17Kj4+XiEhIbrqqqvUu3dvHTt27IL7CUsZwELt27c3ZcuWNTt27DhvvwULFpjg4GCTlJRkFixYYBYsWGA2bNhgjDFm586dJiwszFSsWNFMnDjRPPnkk6Z69eomODjYbNy40bmOOXPmGEmmYcOGJikpyTz33HNm2LBhxs/Pz7Ru3drk5+cbY4zJzMw05cqVM3Xq1DH//ve/zX//+1/zz3/+09SrV++C+1O1alVTp04dExUVZcaOHWuefvpp07BhQ+Pn52dWr17t7Hf99debpk2bFlp+6NChpmzZsubEiRPn3MbevXuNJPPvf//7nH1Onjxp6tWrZwIDA839999vnnvuOZOUlGQkmWeeecbZb+TIkaZChQrO10eOHDEOh8P4+fmZ//znP872YcOGufQrbl0F73mTJk3MTTfdZGbMmGH+8Y9/GH9/f9OrVy+X5efMmWMcDodp0KCBefzxx83MmTPNXXfdZe68885C62vWrJmZPn26GTt2rAkNDTXVqlUzv/32m7Nf//79TUhIiLnmmmvM//3f/5mZM2eali1bGklmzpw5plKlSubBBx80M2bMMPXr1zf+/v7mhx9+cC5/4sQJ06hRI1O+fHnz0EMPmdmzZ5t+/foZh8Nh7r333vO+D0VJTU01fn5+JiUlxflz9ud92rt3r7OtuD9HRXnooYeMJLN+/fpi1bZmzRoTEBBg6tSpY6ZOnWomTJhgYmJiTLly5Vxq2r59uwkNDTVVqlQxkydPNhMnTjRxcXGmUaNG5s9/oiZNmmQcDoe57bbbzKxZs5zrPHuccnJyTPXq1U2lSpXMpEmTzEsvvWQmTJhgmjVrZvbt21es2mEfwg6stHr1auPv72/8/f1NYmKiGT16tFm1apXJzc0t1DcsLMz079+/UHu3bt1MUFCQ+f77751tBw8eNGXLljWtW7d2thX8UWnatKnL+qdOnWokmXfeeccYY8zbb79tJJkvv/zyovenatWqRpJ58803nW3Hjh0zFStWNE2aNHG2vfDCC0aS2bVrl7MtNzfXxMTEFLmPZytO2HnmmWeMJPPqq6+6rD8xMdGEh4ebrKwsY4wxS5cuNZLMN998Y4wx5t133zXBwcGma9eu5rbbbnMu26hRI9O9e/eLrqvgPU9OTnb5I3///fcbf39/c/ToUWOMMUePHjVly5Y1zZs3N7///rvLeguWy83NNbGxsaZBgwYufZYvX24kmUceecTZ1r9/fyPJPPHEE8623377zYSGhhqHw2EWL17sbP/222+NJDN+/Hhn28SJE01YWJj57rvvXGoZO3as8ff3N/v37z/ve3G2zMxMU7FiRRMfH28yMzMLzT9X2CnOz1FRunfvbiS5hL/zady4sYmNjTVHjhxxtn311VfGz8/P9OvXz9nWrVs3ExISYn788Udn2zfffGP8/f1dws6+ffuMv7+/efzxx122s2PHDhMQEOBs37p1q5Fkli5dWqw6cWXgNBas1K5dO6Wlpalr16766quvNHXqVKWkpKhy5cp69913L7h8Xl6eVq9erW7durlcJ1GxYkXdfvvt+vTTT5WVleWyzJAhQxQYGOh8fc899yggIEAffPCBJDlPqS1fvlynT5++6H2qVKmSunfv7nxdcKps69atysjIkCT16tVLISEheu2115z9Vq1apV9++UV33HHHRW/zzz744APFx8erT58+zrbAwECNHDlSx48f17p16yRJSUlJkqT169dLkj755BM1a9ZM7dq10yeffCLpj9M5O3fudPZ1x5AhQ1xuT05KSlJeXp5+/PFHSdKaNWuUnZ2tsWPHKiQkxGXZguU2bdqkw4cPa+jQoS59OnfurLp16+r9998vtN277rrL+e+oqChdffXVCgsLU69evZztV199taKiovTDDz8425YuXaqkpCSVK1dOv/zyi3NKTk5WXl6e8/26EGOM+vXrp8zMTC1YsMDl1OyFFOfnqCgFP+9ly5a94DYOHTqkbdu2acCAAYqOjna2N2rUSO3atXN+JvLy8rRq1Sp169ZNVapUcfarV6+eUlJSXNb51ltvKT8/X7169XJ57+Lj41W7dm2tXbtWkhQZGSnpj5/7kydPXrBWXBkIO7BWs2bN9NZbb+m3337TF198oXHjxik7O1u33nqrvvnmm/Mu+/PPP+vkyZO6+uqrC82rV6+e8vPzC10nULt2bZfX4eHhqlixovOaiTZt2qhnz56aMGGCYmJidMstt2jOnDnKyckp1v7UqlWr0HNH6tSpI0nObURFRalLly4u14q89tprqly5sm666aZibed8fvzxR9WuXVt+fq6/OurVq+ecL0lxcXGqXbu2M9h88sknSkpKUuvWrXXw4EH98MMP+uyzz5Sfn1+isHP2H0hJKleunCQ5r5X6/vvvJUkNGjQ47z5JKnKs69at65xfICQkRBUqVHBpi4yM1FVXXVVofCIjI12u29q9e7dWrlypChUquEzJycmSin/x/JQpU7Rq1SqNGTPGuWxxFefnqCgRERGSpOzs7Atu43zvab169fTLL7/oxIkT+vnnn/X7778X+uwUtezu3btljFHt2rULvX+7du1yvnfVq1fXqFGj9NJLLykmJkYpKSmaOXMm1+tc4bgbC9YLCgpSs2bN1KxZM9WpU0cDBw7U0qVLNX78+Mtah8Ph0BtvvKGNGzfqvffe06pVqzRo0CA99dRT2rhxo8LDwz2ynX79+mnp0qXasGGDGjZsqHfffVdDhw4tFFAutVatWik1NVW///67Nm/erEceeUQNGjRQVFSUPvnkE+3atUvh4eFq0qSJ29s4191Gxhi31+nuNotTS35+vtq1a6fRo0cX2bcgdJxPWlqa/vWvf6lly5Z67LHHilGxZ9StW1fSHxdhlySguis/P18Oh0MrVqwo8r0++/Pz1FNPacCAAXrnnXe0evVqjRw5UpMnT9bGjRt11VVXXc6y4SMIO7iiXHfddZL+OMxeoKintFaoUEFlypRRenp6oXnffvut/Pz8lJCQ4NK+e/du3Xjjjc7Xx48f16FDh9SpUyeXfi1atFCLFi30+OOPa+HCherbt68WL17scmqkKHv27JExxqXegoe4VatWzdnWoUMHVahQQa+99pqaN2+ukydP6s477zzvuouratWq2r59u/Lz813C07fffuucXyApKUlz5szR4sWLlZeXp5YtW8rPz0+tWrVyhp2WLVt6/Pbos9WsWVOStHPnTtWqVeuc+yRJ6enphY5+paenu+yTJ+o5fvz4RR+NKfDbb7+pd+/eCg8P18KFCxUQcPG/wov7c/RnXbp00eTJk/Xqq69eMOyc/Z7+2bfffquYmBiFhYUpJCREoaGh2r17d6F+f162Zs2aMsaoevXqxQqFDRs2VMOGDfXwww9rw4YNuv766zV79mxNmjTpgsvCPpzGgpXWrl1b5P/uC64VOPsQeVhYmI4ePerSz9/fX+3bt9c777zjcmg/MzNTCxcuVKtWrZyH9Qu8+OKLLtfiPP/88zpz5ow6duwo6Y8/VH+uqXHjxpJUrFNZBw8e1Ntvv+18nZWVpfnz56tx48aKj493tgcEBKhPnz56/fXXNXfuXDVs2FCNGjW64PqLo1OnTsrIyNCSJUucbWfOnNGMGTMUHh6uNm3aONsL/iBOmTJFjRo1cl5LkZSUpNTUVG3atOmSHyFo3769ypYtq8mTJ+vUqVMu8wrG4rrrrlNsbKxmz57tMg4rVqzQrl271LlzZ4/V06tXL6WlpWnVqlWF5h09elRnzpw57/KDBg3S/v379fLLL7sdwor7c/RniYmJ6tChg1566aUinziem5urBx54QNIf17Y1btxY8+bNc/ls7dy5U6tXr3b+B8Df318pKSlatmyZ9u/f7+y3a9euQu9Rjx495O/vrwkTJhT6HBljdOTIEef+/Pl9bNiwofz8/Ip9yhj24cgOrDRixAidPHlS3bt3V926dZWbm6sNGzZoyZIlqlatmgYOHOjs27RpU3344Yd6+umnValSJVWvXl3NmzfXpEmTtGbNGrVq1UpDhw5VQECAXnjhBeXk5Gjq1KmFtpmbm6u2bduqV69eSk9P16xZs9SqVSt17dpVkjRv3jzNmjVL3bt3V82aNZWdna3//ve/ioiIKHT0pyh16tTR4MGD9eWXXyouLk6vvPKKMjMzNWfOnEJ9+/Xrp+eee05r167VlClTLuq9S01NLRQMJKlbt24aMmSIXnjhBQ0YMECbN29WtWrV9MYbb+izzz7TM88843Lxaq1atRQfH6/09HSXJ1a3bt1aY8aMkaRLHnYiIiI0ffp03XXXXWrWrJluv/12lStXTl999ZVOnjypefPmKTAwUFOmTNHAgQPVpk0b9enTR5mZmXr22WdVrVo13X///R6r58EHH9S7776rm2++WQMGDFDTpk114sQJ7dixQ2+88Yb27dunmJiYIpedPXu2li1bpkaNGunkyZN69dVXi+zXrl07xcXFnbOGi/k5+rP58+erffv26tGjh7p06aK2bdsqLCxMu3fv1uLFi3Xo0CHns3b+/e9/q2PHjkpMTNTgwYP1+++/a8aMGYqMjNSjjz7qXOeECRO0cuVKJSUlaejQoc7wXL9+fZdnMtWsWVOTJk3SuHHjtG/fPnXr1k1ly5bV3r179fbbb2vIkCF64IEH9NFHH2n48OH629/+pjp16ujMmTNasGCB/P39i3w+EK4Q3rkJDLi0VqxYYQYNGmTq1q1rwsPDTVBQkKlVq5YZMWJEodt0v/32W9O6dWsTGhpqJLncor1lyxaTkpJiwsPDTZkyZcyNN97ofA5PgYJbfNetW2eGDBliypUrZ8LDw03fvn1dbrvdsmWL6dOnj6lSpYoJDg42sbGx5uabbzabNm264P5UrVrVdO7c2axatco0atTIBAcHm7p165739tr69esbPz8/87///a9Y71nBLd7nmhYsWGCM+eOW54EDB5qYmBgTFBRkGjZsaObMmVPkOv/2t78ZSWbJkiXOttzcXFOmTBkTFBRU6Hbw89VV1K3nf76Nf+3atUaSWbt2rUv7u+++a1q2bGlCQ0NNRESE+etf/2oWLVrk0mfJkiWmSZMmJjg42ERHR5u+ffsWeu/69+9vwsLCCtXYpk0bU79+/ULtBeN2tuzsbDNu3DhTq1YtExQUZGJiYkzLli3NtGnTinw0wtnbPt/4FEwF+36uW88v9ufoz06ePGmmTZtmmjVr5vxs1a5d24wYMcLs2bPHpe+HH35orr/+euf73qVLF+fjCM62bt0607RpUxMUFGRq1KhhZs+ebcaPH1/oOTvGGPPmm2+aVq1ambCwMBMWFmbq1q1rhg0bZtLT040xxvzwww9m0KBBpmbNmiYkJMRER0ebG2+80Xz44YfF3kfYx2HMJbySD7gCzJ07VwMHDtSXX37pvCbIFzRp0kTR0dFKTU31dinwEdWqVVODBg20fPlyb5cCXFZcswNYaNOmTdq2bZv69evn7VIAwOu4ZgewyM6dO7V582Y99dRTqlixom677TZvlwQAXseRHcAib7zxhgYOHKjTp09r0aJFhZ4aDABXIq7ZAQAAVuPIDgAAsBphBwAAWI0LlPXHd64cPHhQZcuWLfKrAwAAgO8xxig7O1uVKlU67/f/EXb0x+PT//w9RwAAoHQ4cODAeb/klbAjOR9xf+DAgULfdwQAAHxTVlaWEhISXL6qpiiEHf3/33odERFB2AEAoJS50CUoXKAMAACsRtgBAABWI+wAAACrEXYAAIDVCDsAAMBqhB0AAGA1wg4AALAaYQcAAFiNsAMAAKxG2AEAAFYj7AAAAKsRdgAAgNUIOwAAwGqEHQAAYDXCDgAAsFqAtwsAUPp98Jc+3i6h1Oq0ZZG3SwCsx5EdAABgNcIOAACwGmEHAABYjbADAACsRtgBAABWI+wAAACrEXYAAIDVCDsAAMBqhB0AAGA1wg4AALAaYQcAAFiNsAMAAKxG2AEAAFYj7AAAAKsRdgAAgNUIOwAAwGqEHQAAYDXCDgAAsBphBwAAWI2wAwAArEbYAQAAViPsAAAAqxF2AACA1Qg7AADAaoQdAABgNcIOAACwGmEHAABYjbADAACsRtgBAABWI+wAAACrEXYAAIDVCDsAAMBqhB0AAGA1wg4AALAaYQcAAFiNsAMAAKxG2AEAAFYj7AAAAKsRdgAAgNUIOwAAwGqEHQAAYDXCDgAAsBphBwAAWM2rYWfy5Mlq1qyZypYtq9jYWHXr1k3p6ekufU6dOqVhw4apfPnyCg8PV8+ePZWZmenSZ//+/ercubPKlCmj2NhYPfjggzpz5szl3BUAAOCjvBp21q1bp2HDhmnjxo1as2aNTp8+rfbt2+vEiRPOPvfff7/ee+89LV26VOvWrdPBgwfVo0cP5/y8vDx17txZubm52rBhg+bNm6e5c+fqkUce8cYuAQAAH+MwxhhvF1Hg559/VmxsrNatW6fWrVvr2LFjqlChghYuXKhbb71VkvTtt9+qXr16SktLU4sWLbRixQrdfPPNOnjwoOLi4iRJs2fP1pgxY/Tzzz8rKCjogtvNyspSZGSkjh07poiIiEu6j4CNPvhLH2+XUGp12rLI2yUApVZx/3771DU7x44dkyRFR0dLkjZv3qzTp08rOTnZ2adu3bqqUqWK0tLSJElpaWlq2LChM+hIUkpKirKysvT1118XuZ2cnBxlZWW5TAAAwE4+E3by8/N133336frrr1eDBg0kSRkZGQoKClJUVJRL37i4OGVkZDj7nB10CuYXzCvK5MmTFRkZ6ZwSEhI8vDcAAMBX+EzYGTZsmHbu3KnFixdf8m2NGzdOx44dc04HDhy45NsEAADeEeDtAiRp+PDhWr58udavX6+rrrrK2R4fH6/c3FwdPXrU5ehOZmam4uPjnX2++OILl/UV3K1V0OfPgoODFRwc7OG9AAAAvsirR3aMMRo+fLjefvttffTRR6pevbrL/KZNmyowMFCpqanOtvT0dO3fv1+JiYmSpMTERO3YsUOHDx929lmzZo0iIiJ0zTXXXJ4dAQAAPsurR3aGDRumhQsX6p133lHZsmWd19hERkYqNDRUkZGRGjx4sEaNGqXo6GhFRERoxIgRSkxMVIsWLSRJ7du31zXXXKM777xTU6dOVUZGhh5++GENGzaMozcAAMC7Yef555+XJN1www0u7XPmzNGAAQMkSdOnT5efn5969uypnJwcpaSkaNasWc6+/v7+Wr58ue655x4lJiYqLCxM/fv312OPPXa5dgMAAPgwn3rOjrfwnB2gZHjOjvt4zg7gvlL5nB0AAABPI+wAAACrEXYAAIDVCDsAAMBqhB0AAGA1wg4AALAaYQcAAFiNsAMAAKzmE18EWpq0qt7G2yWUWp/uXeftEgAAVyCO7AAAAKsRdgAAgNUIOwAAwGqEHQAAYDXCDgAAsBphBwAAWI2wAwAArEbYAQAAViPsAAAAqxF2AACA1Qg7AADAaoQdAABgNcIOAACwGmEHAABYjbADAACsRtgBAABWI+wAAACrEXYAAIDVCDsAAMBqhB0AAGA1wg4AALAaYQcAAFiNsAMAAKxG2AEAAFYj7AAAAKsRdgAAgNUIOwAAwGqEHQAAYDXCDgAAsBphBwAAWI2wAwAArEbYAQAAViPsAAAAqxF2AACA1Qg7AADAaoQdAABgNcIOAACwGmEHAABYjbADAACsRtgBAABWI+wAAACrEXYAAIDVCDsAAMBqhB0AAGA1wg4AALAaYQcAAFiNsAMAAKxG2AEAAFYj7AAAAKsRdgAAgNUIOwAAwGqEHQAAYDXCDgAAsBphBwAAWI2wAwAArEbYAQAAVvNq2Fm/fr26dOmiSpUqyeFwaNmyZS7zBwwYIIfD4TJ16NDBpc+vv/6qvn37KiIiQlFRURo8eLCOHz9+GfcCAAD4Mq+GnRMnTujaa6/VzJkzz9mnQ4cOOnTokHNatGiRy/y+ffvq66+/1po1a7R8+XKtX79eQ4YMudSlAwCAUiLAmxvv2LGjOnbseN4+wcHBio+PL3Lerl27tHLlSn355Ze67rrrJEkzZsxQp06dNG3aNFWqVMnjNQMAgNLF56/Z+fjjjxUbG6urr75a99xzj44cOeKcl5aWpqioKGfQkaTk5GT5+fnp888/P+c6c3JylJWV5TIBAAA7+XTY6dChg+bPn6/U1FRNmTJF69atU8eOHZWXlydJysjIUGxsrMsyAQEBio6OVkZGxjnXO3nyZEVGRjqnhISES7ofAADAe7x6GutCevfu7fx3w4YN1ahRI9WsWVMff/yx2rZt6/Z6x40bp1GjRjlfZ2VlEXgAALCUTx/Z+bMaNWooJiZGe/bskSTFx8fr8OHDLn3OnDmjX3/99ZzX+Uh/XAcUERHhMgEAADuVqrDzv//9T0eOHFHFihUlSYmJiTp69Kg2b97s7PPRRx8pPz9fzZs391aZAADAh3j1NNbx48edR2kkae/evdq2bZuio6MVHR2tCRMmqGfPnoqPj9f333+v0aNHq1atWkpJSZEk1atXTx06dNDdd9+t2bNn6/Tp0xo+fLh69+7NnVgAAECSl4/sbNq0SU2aNFGTJk0kSaNGjVKTJk30yCOPyN/fX9u3b1fXrl1Vp04dDR48WE2bNtUnn3yi4OBg5zpee+011a1bV23btlWnTp3UqlUrvfjii97aJQAA4GO8emTnhhtukDHmnPNXrVp1wXVER0dr4cKFniwLAABYpFRdswMAAHCxCDsAAMBqhB0AAGA1wg4AALCax8LO0aNHPbUqAAAAj3Er7EyZMkVLlixxvu7Vq5fKly+vypUr66uvvvJYcQAAACXlVtiZPXu287uk1qxZozVr1mjFihXq2LGjHnzwQY8WCAAAUBJuPWcnIyPDGXaWL1+uXr16qX379qpWrRpf0wAAAHyKW0d2ypUrpwMHDkiSVq5cqeTkZEmSMUZ5eXmeqw4AAKCE3Dqy06NHD91+++2qXbu2jhw5oo4dO0qStm7dqlq1anm0QAAAgJJwK+xMnz5d1apV04EDBzR16lSFh4dLkg4dOqShQ4d6tEAAAICScCvsBAYG6oEHHijUfv/995e4IAAAAE9y+4tA09PTNWPGDO3atUuSVK9ePY0YMUJXX321x4oDAAAoKbcuUH7zzTfVoEEDbd68Wddee62uvfZabdmyRQ0aNNCbb77p6RoBAADc5taRndGjR2vcuHF67LHHXNrHjx+v0aNHq2fPnh4pDgBwcfbce7u3SyjVaj270Nsl4BJw68jOoUOH1K9fv0Ltd9xxhw4dOlTiogAAADzFrbBzww036JNPPinU/umnnyopKanERQEAAHiKW6exunbtqjFjxmjz5s1q0aKFJGnjxo1aunSpJkyYoHfffdelLwAAV5rMZTO8XUKpFtdthMfW5VbYKXiWzqxZszRr1qwi50mSw+HgicoAAMCr3Ao7+fn5nq4DAADgknD7OTuAt41t0MfbJZRaT+5c5O0SAOCycesCZUlat26dunTpolq1aqlWrVrq2rVrkRctAwAAeJNbYefVV19VcnKyypQpo5EjR2rkyJEKDQ1V27ZttXAhzygAAAC+w63TWI8//rimTp3q8l1YI0eO1NNPP62JEyfq9tt5qBUAAPANbh3Z+eGHH9SlS5dC7V27dtXevXtLXBQAAICnuBV2EhISlJqaWqj9ww8/VEJCQomLAgAA8BS3TmP94x//0MiRI7Vt2za1bNlSkvTZZ59p7ty5evbZZz1aIAAAQEm4FXbuuecexcfH66mnntLrr78uSapXr56WLFmiW265xaMFAgAAlITbz9np3r27unfv7slaAAAAPM6ta3Zq1KihI0eOFGo/evSoatSoUeKiAAAAPMWtsLNv374iv/MqJydHP/30U4mLAgAA8JSLOo119reZr1q1SpGRkc7XeXl5Sk1NVbVq1TxWHAAAQEldVNjp1q2bpD++zbx///4u8wIDA1WtWjU99dRTHisOAACgpC4q7BR823n16tX15ZdfKiYm5pIUBQAA4Clu3Y3FU5IBAEBpcVEXKKelpWn58uUubfPnz1f16tUVGxurIUOGKCcnx6MFAgAAlMRFhZ3HHntMX3/9tfP1jh07NHjwYCUnJ2vs2LF67733NHnyZI8XCQAA4K6LCjvbtm1T27Ztna8XL16s5s2b67///a9GjRql5557zvlEZQAAAF9wUWHnt99+U1xcnPP1unXr1LFjR+frZs2a6cCBA56rDgAAoIQuKuzExcU5L07Ozc3Vli1b1KJFC+f87OxsBQYGerZCAACAEriosNOpUyeNHTtWn3zyicaNG6cyZcooKSnJOX/79u2qWbOmx4sEAABw10Xdej5x4kT16NFDbdq0UXh4uObNm6egoCDn/FdeeUXt27f3eJEAAADuuqiwExMTo/Xr1+vYsWMKDw+Xv7+/y/ylS5cqPDzcowUCAACUhFsPFTz7O7HOFh0dXaJiAAAAPM2tsHPq1CnNmDFDa9eu1eHDh51fI1Fgy5YtHikOAACgpNwKO4MHD9bq1at166236q9//ascDoen6wIAAPAIt8LO8uXL9cEHH+j666/3dD0AAAAedVG3nheoXLmyypYt6+laAAAAPM6tsPPUU09pzJgx+vHHHz1dDwAAgEe5dRrruuuu06lTp1SjRg2VKVOm0FOTf/31V48UBwAAUFJuhZ0+ffrop59+0hNPPKG4uDguUAYAAD7LrbCzYcMGpaWl6dprr/V0PQAAAB7l1jU7devW1e+//+7pWgAAADzOrbDz5JNP6h//+Ic+/vhjHTlyRFlZWS4TAACAr3DrNFaHDh0kSW3btnVpN8bI4XAoLy+v5JUBAAB4gFthZ+3atZ6uAwAA4JJwK+y0adPG03UAAABcEm6FnfXr1593fuvWrd0qBgAAwNPcCjs33HBDobazn7XDNTsAAMBXuHU31m+//eYyHT58WCtXrlSzZs20evVqT9cIAADgNreO7ERGRhZqa9eunYKCgjRq1Cht3ry5xIUBAAB4gltHds4lLi5O6enpnlwlAABAibh1ZGf79u0ur40xOnTokJ588kk1btzYE3UBAAB4hFthp3HjxnI4HDLGuLS3aNFCr7zyikcKAwAA8AS3ws7evXtdXvv5+alChQoKCQnxSFEAAACe4tY1O1WrVtWePXv0wgsvaOLEiRo/fryGDh2qQYMGadCgQcVez/r169WlSxdVqlRJDodDy5Ytc5lvjNEjjzyiihUrKjQ0VMnJydq9e7dLn19//VV9+/ZVRESEoqKiNHjwYB0/ftyd3QIAABZyK+xMmDBB7du3V2pqqn755ZdCt6IX14kTJ3Tttddq5syZRc6fOnWqnnvuOc2ePVuff/65wsLClJKSolOnTjn79O3bV19//bXWrFmj5cuXa/369RoyZIg7uwUAACzk1mms2bNna+7cubrzzjtLtPGOHTuqY8eORc4zxuiZZ57Rww8/rFtuuUWSNH/+fMXFxWnZsmXq3bu3du3apZUrV+rLL7/UddddJ0maMWOGOnXqpGnTpqlSpUolqg8AAJR+bh3Zyc3NVcuWLT1di4u9e/cqIyNDycnJzrbIyEg1b95caWlpkqS0tDRFRUU5g44kJScny8/PT59//vk5152Tk6OsrCyXCQAA2MmtsHPXXXdp4cKFnq7FRUZGhqQ/nt1ztri4OOe8jIwMxcbGuswPCAhQdHS0s09RJk+erMjISOeUkJDg4eoBAICvcOs01qlTp/Tiiy/qww8/VKNGjRQYGOgy/+mnn/ZIcZfKuHHjNGrUKOfrrKwsAg8AAJZy+6GCBQ8P3Llzp8u8s78QtCTi4+MlSZmZmapYsaKzPTMz07nt+Ph4HT582GW5M2fO6Ndff3UuX5Tg4GAFBwd7pE4AAODb3Ao7a9eu9XQdhVSvXl3x8fFKTU11hpusrCx9/vnnuueeeyRJiYmJOnr0qDZv3qymTZtKkj766CPl5+erefPml7xGAADg+9wKO55y/Phx7dmzx/l679692rZtm6Kjo1WlShXdd999mjRpkmrXrq3q1avrX//6lypVqqRu3bpJkurVq6cOHTro7rvv1uzZs3X69GkNHz5cvXv35k4sAAAgycthZ9OmTbrxxhudrwuuo+nfv7/mzp2r0aNH68SJExoyZIiOHj2qVq1aaeXKlS5Pan7ttdc0fPhwtW3bVn5+furZs6eee+65y74vAADAN3k17Nxwww2Fvl/rbA6HQ4899pgee+yxc/aJjo6+5HeGAQCA0sutW88BAABKC8IOAACwGmEHAABYjbADAACsRtgBAABWI+wAAACrEXYAAIDVCDsAAMBqhB0AAGA1wg4AALAaYQcAAFiNsAMAAKxG2AEAAFYj7AAAAKsRdgAAgNUIOwAAwGqEHQAAYDXCDgAAsBphBwAAWI2wAwAArEbYAQAAViPsAAAAqxF2AACA1Qg7AADAaoQdAABgNcIOAACwGmEHAABYjbADAACsRtgBAABWI+wAAACrEXYAAIDVCDsAAMBqhB0AAGA1wg4AALAaYQcAAFiNsAMAAKxG2AEAAFYj7AAAAKsRdgAAgNUIOwAAwGqEHQAAYDXCDgAAsBphBwAAWI2wAwAArEbYAQAAViPsAAAAqxF2AACA1Qg7AADAaoQdAABgNcIOAACwGmEHAABYjbADAACsRtgBAABWI+wAAACrEXYAAIDVCDsAAMBqhB0AAGA1wg4AALAaYQcAAFiNsAMAAKxG2AEAAFYj7AAAAKsRdgAAgNUIOwAAwGqEHQAAYDWfDjuPPvqoHA6Hy1S3bl3n/FOnTmnYsGEqX768wsPD1bNnT2VmZnqxYgAA4Gt8OuxIUv369XXo0CHn9Omnnzrn3X///Xrvvfe0dOlSrVu3TgcPHlSPHj28WC0AAPA1Ad4u4EICAgIUHx9fqP3YsWN6+eWXtXDhQt10002SpDlz5qhevXrauHGjWrRocblLBQAAPsjnj+zs3r1blSpVUo0aNdS3b1/t379fkrR582adPn1aycnJzr5169ZVlSpVlJaWdt515uTkKCsry2UCAAB28umw07x5c82dO1crV67U888/r7179yopKUnZ2dnKyMhQUFCQoqKiXJaJi4tTRkbGedc7efJkRUZGOqeEhIRLuBcAAMCbfPo0VseOHZ3/btSokZo3b66qVavq9ddfV2hoqNvrHTdunEaNGuV8nZWVReABAMBSPn1k58+ioqJUp04d7dmzR/Hx8crNzdXRo0dd+mRmZhZ5jc/ZgoODFRER4TIBAAA7laqwc/z4cX3//feqWLGimjZtqsDAQKWmpjrnp6ena//+/UpMTPRilQAAwJf49GmsBx54QF26dFHVqlV18OBBjR8/Xv7+/urTp48iIyM1ePBgjRo1StHR0YqIiNCIESOUmJjInVgAAMDJp8PO//73P/Xp00dHjhxRhQoV1KpVK23cuFEVKlSQJE2fPl1+fn7q2bOncnJylJKSolmzZnm5agAA4Et8OuwsXrz4vPNDQkI0c+ZMzZw58zJVBAAASptSdc0OAADAxSLsAAAAqxF2AACA1Qg7AADAaoQdAABgNcIOAACwGmEHAABYjbADAACsRtgBAABWI+wAAACrEXYAAIDVCDsAAMBqhB0AAGA1wg4AALAaYQcAAFiNsAMAAKxG2AEAAFYj7AAAAKsRdgAAgNUIOwAAwGqEHQAAYDXCDgAAsBphBwAAWI2wAwAArEbYAQAAViPsAAAAqxF2AACA1Qg7AADAaoQdAABgNcIOAACwGmEHAABYjbADAACsRtgBAABWI+wAAACrEXYAAIDVCDsAAMBqhB0AAGA1wg4AALAaYQcAAFiNsAMAAKxG2AEAAFYj7AAAAKsRdgAAgNUIOwAAwGqEHQAAYDXCDgAAsBphBwAAWI2wAwAArEbYAQAAViPsAAAAqxF2AACA1Qg7AADAaoQdAABgNcIOAACwGmEHAABYjbADAACsRtgBAABWI+wAAACrEXYAAIDVCDsAAMBqhB0AAGA1wg4AALAaYQcAAFiNsAMAAKxmTdiZOXOmqlWrppCQEDVv3lxffPGFt0sCAAA+wIqws2TJEo0aNUrjx4/Xli1bdO211yolJUWHDx/2dmkAAMDLrAg7Tz/9tO6++24NHDhQ11xzjWbPnq0yZcrolVde8XZpAADAy0p92MnNzdXmzZuVnJzsbPPz81NycrLS0tK8WBkAAPAFAd4uoKR++eUX5eXlKS4uzqU9Li5O3377bZHL5OTkKCcnx/n62LFjkqSsrKwLbu9M/pkSVHtlK877ezFy8k57dH1XEk+PxUnGwm2eHovsHMaiJDw5Htknf/fYuq5EocUYi4LxMsact1+pDzvumDx5siZMmFCoPSEhwQvVXDkiIyO9XQL+P89EvuntElCAsfAtL7zh7QrgNKbYPbOzs8/7N6bUh52YmBj5+/srMzPTpT0zM1Px8fFFLjNu3DiNGjXK+To/P1+//vqrypcvL4fDcUnrvVSysrKUkJCgAwcOKCIiwtvlXNEYC9/CePgOxsJ32DIWxhhlZ2erUqVK5+1X6sNOUFCQmjZtqtTUVHXr1k3SH+ElNTVVw4cPL3KZ4OBgBQcHu7RFRUVd4kovj4iIiFL9g2sTxsK3MB6+g7HwHTaMRXHOGpT6sCNJo0aNUv/+/XXdddfpr3/9q5555hmdOHFCAwcO9HZpAADAy6wIO7fddpt+/vlnPfLII8rIyFDjxo21cuXKQhctAwCAK48VYUeShg8ffs7TVleC4OBgjR8/vtDpOVx+jIVvYTx8B2PhO660sXCYC92vBQAAUIqV+ocKAgAAnA9hBwAAWI2wAwAArEbYAQAAViPseMnzzz+vRo0aOR/olJiYqBUrVkiS9u3bJ4fDUeS0dOlSSdJXX32lPn36KCEhQaGhoapXr56effbZQtv5+OOP9Ze//EXBwcGqVauW5s6dW+w6riS+Mh7VqlUrcjvDhg275O+Br/CVscjLy9O//vUvVa9eXaGhoapZs6YmTpx4we/gscnlGItDhw7p9ttvV506deTn56f77ruvyFqWLl2qunXrKiQkRA0bNtQHH3xwSffd11yOsXjrrbfUrl07VahQwbmNVatWufQptZ8LA6949913zfvvv2++++47k56ebh566CETGBhodu7cac6cOWMOHTrkMk2YMMGEh4eb7OxsY4wxL7/8shk5cqT5+OOPzffff28WLFhgQkNDzYwZM5zb+OGHH0yZMmXMqFGjzDfffGNmzJhh/P39zcqVK4tVx5XEV8bj8OHDLttZs2aNkWTWrl17ud8Sr/GVsXj88cdN+fLlzfLly83evXvN0qVLTXh4uHn22Wcv+3viLZdjLPbu3WtGjhxp5s2bZxo3bmzuvffeQnV89tlnxt/f30ydOtV888035uGHHzaBgYFmx44dl+ut8LrLMRb33nuvmTJlivniiy/Md999Z8aNG2cCAwPNli1bnH1K6+eCsONDypUrZ1566aUi5zVu3NgMGjTovMsPHTrU3Hjjjc7Xo0ePNvXr13fpc9ttt5mUlBS367iS+MJ43HvvvaZmzZomPz//Iiq3jzfGonPnzoXW26NHD9O3b9+LLd8qnh6Ls7Vp06bIsNOrVy/TuXNnl7bmzZubv//978Ur2lKXciwKXHPNNWbChAnO16X1c8FpLB+Ql5enxYsX68SJE0pMTCw0f/Pmzdq2bZsGDx583vUcO3ZM0dHRztdpaWlKTk526ZOSkqK0tDS36rhS+Mp45Obm6tVXX9WgQYNK7RfUlpQ3x6Jly5ZKTU3Vd999J+mP0wCffvqpOnbsWJJdKrUu1VgUx8V+dmx3ucYiPz9f2dnZLn1K7efC22nrSrZ9+3YTFhZm/P39TWRkpHn//feL7HfPPfeYevXqnXddn332mQkICDCrVq1yttWuXds88cQTLv3ef/99I8mcPHnyouuwna+MR4ElS5YYf39/89NPP7mxN6WbL4xFXl6eGTNmjHE4HCYgIMA4HI5Cy1wJLvVYnO1cR3YCAwPNwoULXdpmzpxpYmNji7cTlricY2GMMVOmTDHlypUzmZmZzrbS+rkg7HhRTk6O2b17t9m0aZMZO3asiYmJMV9//bVLn5MnT5rIyEgzbdq0c65nx44dJiYmxkycONGlvbh/XItTx5XAV8ajQPv27c3NN99cgj0qvXxhLBYtWmSuuuoqs2jRIrN9+3Yzf/58Ex0dbebOneuhvSwdLvVYnI2wc36Xcyxee+01U6ZMGbNmzRqX9tL6uSDs+JC2bduaIUOGuLTNnz/fBAYGmsOHDxe5zNdff21iY2PNQw89VGheUlJSoV8cr7zyiomIiLjoOq5E3hyPffv2GT8/P7Ns2TL3d8Ai3hiLq666yvznP/9x6TNx4kRz9dVXu7kXdvD0WJztXGEnISHBTJ8+3aXtkUceMY0aNbqo2m1zqcZi0aJFJjQ01CxfvrzQvNL6ueCaHR+Sn5+vnJwcl7aXX35ZXbt2VYUKFQr1//rrr3XjjTeqf//+evzxxwvNT0xMVGpqqkvbmjVrLng9TlF1XIm8OR5z5sxRbGysOnfuXMK9sIM3xuLkyZPy83P9Fenv76/8/PyS7Eqp5+mxKA53f5fZ7lKMxaJFizRw4EAtWrSoyN8/pfZz4e20daUaO3asWbdundm7d6/Zvn27GTt2rHE4HGb16tXOPrt37zYOh8OsWLGi0PI7duwwFSpUMHfccYfL7YZnp/mC22sffPBBs2vXLjNz5sxCt9cWp44rga+MhzF/nBOvUqWKGTNmzKXbYR/mK2PRv39/U7lyZecttm+99ZaJiYkxo0ePvrRvgA+5HGNhjDFbt241W7duNU2bNjW333672bp1q8vpmYLrS6ZNm2Z27dplxo8ff8Xden45xuK1114zAQEBZubMmS59jh496uxTWj8XhB0vGTRokKlataoJCgoyFSpUMG3bti0UMMaNG2cSEhJMXl5eoeXHjx9vJBWaqlat6tJv7dq1pnHjxiYoKMjUqFHDzJkz56LruBL4yngYY8yqVauMJJOenu7JXSw1fGUssrKyzL333muqVKliQkJCTI0aNcw///lPk5OT4+ld9lmXayyK0+f11183derUMUFBQaZ+/fpX3I0Ul2Ms2rRpU2Sf/v37O/uU1s+Fwxhff+whAACA+7hmBwAAWI2wAwAArEbYAQAAViPsAAAAqxF2AACA1Qg7AADAaoQdAABgNcIOACvNnTtXUVFR3i4DgA/goYIArPT7778rOztbsbGx3i4FgJcRdgAAgNU4jQWg1Nq3b58cDkeh6YYbbih0GuvRRx9V48aN9cILLyghIUFlypRRr169dOzYMe/tAIDLgrADoNRKSEjQoUOHnNPWrVtVvnx5tW7dusj+e/bs0euvv6733ntPK1eu1NatWzV06NDLXDWAy42wA6DU8vf3V3x8vOLj4xUVFaX/+7//U2Jioh599NEi+586dUrz589X48aN1bp1a82YMUOLFy9WRkbG5S0cwGVF2AFghUGDBik7O1sLFy6Un1/Rv9qqVKmiypUrO18nJiYqPz9f6enpl6tMAF4Q4O0CAKCkJk2apFWrVumLL75Q2bJlvV0OAB/DkR0Apdqbb76pxx57TK+//rpq1qx53r779+/XwYMHna83btwoPz8/XX311Ze6TABexJEdAKXWzp071a9fP40ZM0b169d3XnsTFBRUZP+QkBD1799f06ZNU1ZWlkaOHKlevXopPj7+cpYN4DLjyA6AUmvTpk06efKkJk2apIoVKzqnHj16FNm/Vq1a6tGjhzp16qT27durUaNGmjVr1mWuGsDlxkMFAVwRHn30US1btkzbtm3zdikALjOO7AAAAKsRdgAAgNU4jQUAAKzGkR0AAGA1wg4AALAaYQcAAFiNsAMAAKxG2AEAAFYj7AAAAKsRdgAAgNUIOwAAwGqEHQAAYLX/B41gQLNqG6f2AAAAAElFTkSuQmCC\n"
          },
          "metadata": {}
        }
      ]
    }
  ]
}